Workbook

Sheet info
A1: SCENARIO SIMULATION TOOL|MARITIME SHIPPING DECARBONISATION
E2: SHEET INDEX | O2: COLOUR CODING
A3: Title | B3: Pacific Shipping Tool | E3: Name | G3: Function | P3: Model Inputs, Output Dashboard
A4: Developers | B4: Edoardo Santagata | E4: 1 | F4: MAIN | G4: Central input/output dashboard containing all scenario parameters and aggregated annual results (2025–2050) for fuel consumption, emissions, costs, renewable energy capacity, and IMO GHG Fuel Standard compliance. | P4: Detailed Parametrisation, Assumptions
A5: Supervision | B5: Anna Bruce | E5: 2 | F5: current | G5: Baseline fleet fuel consumption summary by fuel type in energy (TJ) and mass (tonnes). | P5: Energy Consumption by Vessel Type
B6: Iain MacGill | E6: 3 | F6: consumptions per type | G6: Aggregated annual energy consumption by vessel type with assigned baseline fuel and operational measure eligibility flags. | P6: Raw Data
B7: Atul Raturi | E7: 4 | F7: dictionary | G7: Vessel-type-specific clean fuel suitability proportions and operational measure applicability assumptions.
A8: Affiliation | B8: University of New South Wales (UNSW) | E8: 5 | F8: efficiency | G8: Energy conversion ratios between fossil and clean fuels, and engine/system efficiency values used in renewable energy capacity calculations.
B9: Centre for Sustainable Development Reform (CSDR), UNSW | E9: 6 | F9: re | G9: Renewable energy generation capacity (MW by source) required to produce the clean fuels consumed under the modelled scenario.
B10: Collaboration on Energy and Environmental Markets (CEEM), UNSW | E10: 7 | F10: production | G10: Production pathway proportions for each clean fuel, used to derive weighted-average emission intensities and costs.
A11: Version | B11: 2 | E11: 8 | F11: emissions | G11: Well-to-wake CO₂-equivalent emission factors for fossil and clean fuels, disaggregated by production pathway.
A12: Release Date | B12: 46063 | E12: 9 | F12: cost | G12: Unit fuel costs ($/TJ) for fossil and clean fuels, disaggregated by production pathway.
E13: 10 | F13: raw | G13: Fleet input data with one row per vessel containing type classifications, physical characteristics, operational parameters, and energy consumption.
E14: 11-56 | F14: 1-23 + (RU) | G14: Per-vessel-type decarbonisation trajectory calculations applying logistic S-curve adoption functions for operational measures and clean fuel transitions. (RU) sheets incorporate IMO GHG Fuel Standard compliance with BT/DCT thresholds and Revenue Unit calculations.
A17: Correspondence
A18: Name | B18: Edoardo Santagata
A19: Affiliation | B19: Centre for Sustainable Development Reform (CSDR), UNSW
A20: email | B20: edoardo.santagata@unsw.edu.au
A22: Copyright Information
A23: Disclaimer | B23: THE SOFTWARE IS PROVIDED "AS IS", WITHOUT WARRANTY OF ANY KIND, EXPRESS OR IMPLIED, INCLUDING BUT NOT LIMITED TO THE WARRANTIES OF MERCHANTABILITY, FITNESS FOR A PARTICULAR PURPOSE AND NON-INFRINGEMENT. IN NO EVENT SHALL THE AUTHORS OR COPYRIGHT HOLDERS BE LIABLE FOR ANY CLAIM, DAMAGES OR OTHER LIABILITY, WHETHER IN AN ACTION OF CONTRACT, TORT OR OTHERWISE, ARISING FROM, OUT OF OR IN CONNECTION WITH THE SOFTWARE OR THE USE OR OTHER DEALINGS IN THE SOFTWARE. | E23: USER MANUAL
A24: Distribution License | B24: © Copyright 2026 University of New South Wales (UNSW) | E24: Overview This tool simulates decarbonisation scenarios for maritime shipping fleets over the period 2025–2050. It models the transition from fossil fuels to clean fuels and operational efficiency measures using logistic S-curve adoption functions, and calculates annual fuel consumption, well-to-wake emissions, costs, renewable energy capacity requirements, and IMO carbon levy (Revenue Unit) impacts for each scenario. The tool is designed to work with fleet data produced by Function 2 of this repository, but can also accept user-provided fleet data from any source, provided it follows the required format in the raw sheet. Getting Started Populate the raw sheet with your vessel fleet data. The sample data included contains one dummy vessel per considered vessel type for demonstration purposes. Replace this with your actual fleet data, ensuring the following columns are present: Flag, Vessel Name, Imo, Vessel Type - Generic, Draught, Built, Length, Capacity - Dwt, Average Speed, Vessel Type - Detailed, Capacity - Gt, Operational Days, Vessel Type - Simplified, Vessel Type - Contextual, Estimated DWT, Fuel Consumption, Fuel Type, Energy Consumption (TJ/year). If using output from shippinganalysis.py (Function 2), the format will already match. Review the consumptions per type sheet, which automatically aggregates energy consumption from raw by vessel type. Check that the Fuel Type assignment and operational measure eligibility flags (HULL, SLOW, SAIL) are appropriate for your fleet. These flags determine which measures are applied to each vessel type in the scenario simulation. Set scenario parameters in the MAIN sheet. The key user inputs are located in cells A1–D12: Annual Growth Rate (cell B1): Fleet-wide annual growth rate applied to energy consumption (default: 2.1%) Operational Measures (rows 4–6): For each measure (hull coating + propeller upgrades, slow steaming, sailing & hybrid), set the logistic adoption rate k, energy savings fraction, and inflection year t₀ Clean Fuels (row 8): Set the logistic adoption rate k and inflection year t₀ for clean fuel uptake Fuel Swaps (rows 11–12): Set adoption parameters for HFO→LFO and MDO→MGO fuel swaps (set k = 0 to disable)
B25: Permission is hereby granted, free of charge, to any person obtaining a copy of this software and associated documentation files (the "Software"), to deal in the Software without restriction, including without limitation the rights to use, copy, modify, merge, publish, distribute, sublicense, and/or sell copies of the Software, and to permit persons to whom the Software is furnished to do so, subject to the following conditions:
B26: The above copyright notice and this permission notice shall be included in all copies or substantial portions of the Software.
A27: Citation | B27: While this tool is published under the conditions of the open source MIT license by making sure that the code can be used, edited, and re-distributed by others, we require that the tool developers are acknowledged by using the following citation:
B28: Santagata, E. 2026. Planning Frameworks and Tools for Secure and Resilient Clean Energy Transitions in Pacific Island Countries and Territories. PhD Thesis, UNSW Sydney. DOI: https://doi.org/10.26190/unsworks/31988
E29: Review assumption sheets as needed. The dictionary, efficiency, production, emissions, cost, and re sheets contain detailed parametrisation that can be adjusted for different scenarios or regions. See sheet descriptions below. Read results from the MAIN sheet. The output dashboard (rows 14 onwards and columns G onwards) presents annual time series for: fuel consumption by type (TJ), fossil vs clean fuel totals, consumption by vessel type, well-to-wake emissions (tCO₂-e), operational costs, renewable energy capacity requirements (MW by source), and IMO GHG Fuel Standard compliance indicators (BT and DCT thresholds, Revenue Unit requirements). Scenario Design The tool supports both normative and exploratory scenario approaches: Normative scenarios: Work backwards from a target (e.g. IMO 2050 net-zero, IEA Net Zero) by calibrating k and t₀ parameters to meet the desired emissions trajectory Exploratory scenarios: Test "what if" assumptions by varying adoption rates, measure eligibility, or fuel suitability proportions Each numbered vessel type sheet (1–23) and its corresponding RU variant (1–23 RU) can be inspected to understand the per-type transition dynamics. The N sheets model the scenario without IMO carbon levy constraints; the N (RU) sheets model the same scenario under IMO GHG Fuel Standard compliance obligations. IMO GHG Fuel Standard (Revenue Units) The tool includes the IMO's proposed GHG Fuel Standard framework with two compliance thresholds: BT (Below Threshold): The lower bound carbon intensity target DCT (Deemed Compliance Threshold): The upper bound These thresholds tighten annually from 2028 to 2050 (columns BT and DCT in MAIN). Vessels that exceed the DCT must purchase Revenue Units (RUs). The N (RU) sheets calculate per-type compliance under this framework, and MAIN aggregates fleet-wide RU requirements, costs, and income.

Sheet MAIN
A1: Annual Growth Rate | B1: 0.021 | G1: Year | H1: HFO | I1: LFO | J1: MDO | K1: MGO | L1: LNG | M1: Hydrogen (Combustion) | N1: Hydrogen (Fuel Cells) | O1: Ammonia | P1: Methanol | Q1: bio-LNG | R1: bio-Ethanol | S1: HVO | T1: Synthetic Diesel | U1: Electricity (Battery) | V1: Fossil Fuels | W1: Clean Fuels | Y1: TJ elec | Z1: RE MW | AA1: Solar | AB1: Wind | AC1: Hydro | AD1: Geothermal | AE1: Biomass | AF1: ='consumptions per type'!A2 -> Passenger Vessel | AG1: ='consumptions per type'!A3 -> General Cargo | AH1: ='consumptions per type'!A4 -> Special Craft | AI1: ='consumptions per type'!A5 -> Supply Vessel | AJ1: ='consumptions per type'!A6 -> Passenger/Cargo Ship | AK1: ='consumptions per type'!A7 -> Container Ship | AL1: ='consumptions per type'!A8 -> Ro-Ro/Vehicles Carrier | AM1: ='consumptions per type'!A9 -> LNG Tanker | AN1: ='consumptions per type'!A10 -> Other Special Craft | AO1: ='consumptions per type'!A11 -> Oil/Chemical Tanker | AP1: ='consumptions per type'!A12 -> Reefer | AQ1: ='consumptions per type'!A13 -> Bulk Carrier | AR1: ='consumptions per type'!A14 -> LPG Tanker | AS1: ='consumptions per type'!A15 -> Ro-Ro/Passenger Vessel | AT1: ='consumptions per type'!A16 -> Crude Oil Tanker | AU1: ='consumptions per type'!A17 -> Oil Products Tanker | AV1: ='consumptions per type'!A18 -> Heavy Load Carrier | AW1: ='consumptions per type'!A19 -> Landing Craft | AX1: ='consumptions per type'!A20 -> High Speed Craft | AY1: ='consumptions per type'!A21 -> Other Cargo | AZ1: ='consumptions per type'!A22 -> Special Cargo | BA1: ='consumptions per type'!A23 -> Other Passenger | BB1: ='consumptions per type'!A24 -> Special Passenger Vessel | BC1: Effective HCP | BD1: Effective SS | BE1: Effective SH | BF1: Effective CF | BG1: Obliged under Rus | BH1: BT | BI1: DCT | BK1: HFO | BL1: LFO | BM1: MDO | BN1: MGO | BO1: LNG | BP1: Hydrogen (Combustion) | BQ1: Hydrogen (Fuel Cells) | BR1: Ammonia | BS1: Methanol | BT1: bio-LNG | BU1: bio-Ethanol | BV1: HVO | BW1: Synthetic Diesel | BX1: Electricity (Battery) | BY1: Fossil Fuels | BZ1: Clean Fuels | CB1: Emissions | CC1: HFO | CD1: LFO | CE1: MDO | CF1: MGO | CG1: LNG | CH1: Hydrogen (Combustion) | CI1: Hydrogen (Fuel Cells) | CJ1: Ammonia | CK1: Methanol | CL1: bio-LNG | CM1: bio-Ethanol | CN1: HVO | CO1: Synthetic Diesel | CP1: Electricity (Battery) | CQ1: Fossil Fuels | CR1: Clean Fuels | CS1: TOTAL EM | CT1: TOTAL EM f | CU1: BT factor diff | CV1: DCT factor diff | CW1: BT | CX1: DCT | CY1: RU req | CZ1: Cost | DA1: Zone | DB1: Ru gen | DC1: Income | DD1: Year | DE1: RU | DF1: Emissions | DH1: BCT | DI1: DCT | DJ1: belwo helper | DK1: between | DL1: above | DN1: RU Mt | DO1: Baseline en 93.3 | DQ1: HFO | DR1: LFO | DS1: MDO | DT1: MGO | DU1: LNG | DV1: HFO em | DW1: LFO em | DX1: MDO em | DY1: MGO em | DZ1: LNG em | EA1: EMISSIONS | EB1: RU Requirements | ED1: OP COSTS | EE1: HFO | EF1: LFO | EG1: MDO | EH1: MGO | EI1: LNG | EJ1: Hydrogen (Combustion) | EK1: Hydrogen (Fuel Cells) | EL1: Ammonia | EM1: Methanol | EN1: bio-LNG | EO1: bio-Ethanol | EP1: HVO | EQ1: Synthetic Diesel | ER1: Electricity (Battery)
G2: 2025 | H2: ='2'!AB8+'6'!AB8+'7'!AB8+'9'!AB8+'11'!AB8+'12'!AB8+'13'!AB8+'16'!AB8+'17'!AB8+'18'!AB8+'22'!AB8 -> 380.37773 | I2: ='1'!AB8+'2'!AC8+'5'!AB8+'6'!AC8+'7'!AC8+'9'!AC8+'11'!AC8+'12'!AC8+'13'!AC8+'15'!AB8+'16'!AC8+'17'!AC8+'18'!AC8+'19'!AB8+'22'!AC8 -> 213.57532 | K2: ='3'!AB8+'4'!AB8+'10'!AB8+'20'!AB8+'21'!AB8+'23'!AB8 -> 21.924534 | L2: ='8'!AB8+'14'!AB8 -> 202.51922 | M2: ='1'!AD8+'2'!AD8+'3'!AD8+'4'!AD8+'5'!AD8+'6'!AD8+'7'!AD8+'8'!AD8+'9'!AD8+'10'!AD8+'11'!AD8+'12'!AD8+'13'!AD8+'14'!AD8+'15'!AD8+'16'!AD8+'17'!AD8+'18'!AD8+'19'!AD8+'20'!AD8+'21'!AD8+'22'!AD8+'23'!AD8 -> 0 | N2: ='1'!AE8+'2'!AE8+'3'!AE8+'4'!AE8+'5'!AE8+'6'!AE8+'7'!AE8+'8'!AE8+'9'!AE8+'10'!AE8+'11'!AE8+'12'!AE8+'13'!AE8+'14'!AE8+'15'!AE8+'16'!AE8+'17'!AE8+'18'!AE8+'19'!AE8+'20'!AE8+'21'!AE8+'22'!AE8+'23'!AE8 -> 0 | O2: ='1'!AF8+'2'!AF8+'3'!AF8+'4'!AF8+'5'!AF8+'6'!AF8+'7'!AF8+'8'!AF8+'9'!AF8+'10'!AF8+'11'!AF8+'12'!AF8+'13'!AF8+'14'!AF8+'15'!AF8+'16'!AF8+'17'!AF8+'18'!AF8+'19'!AF8+'20'!AF8+'21'!AF8+'22'!AF8+'23'!AF8 -> 0 | P2: ='1'!AG8+'2'!AG8+'3'!AG8+'4'!AG8+'5'!AG8+'6'!AG8+'7'!AG8+'8'!AG8+'9'!AG8+'10'!AG8+'11'!AG8+'12'!AG8+'13'!AG8+'14'!AG8+'15'!AG8+'16'!AG8+'17'!AG8+'18'!AG8+'19'!AG8+'20'!AG8+'21'!AG8+'22'!AG8+'23'!AG8 -> 0 | Q2: ='1'!AH8+'2'!AH8+'3'!AH8+'4'!AH8+'5'!AH8+'6'!AH8+'7'!AH8+'8'!AH8+'9'!AH8+'10'!AH8+'11'!AH8+'12'!AH8+'13'!AH8+'14'!AH8+'15'!AH8+'16'!AH8+'17'!AH8+'18'!AH8+'19'!AH8+'20'!AH8+'21'!AH8+'22'!AH8+'23'!AH8 -> 0 | R2: ='1'!AI8+'2'!AI8+'3'!AI8+'4'!AI8+'5'!AI8+'6'!AI8+'7'!AI8+'8'!AI8+'9'!AI8+'10'!AI8+'11'!AI8+'12'!AI8+'13'!AI8+'14'!AI8+'15'!AI8+'16'!AI8+'17'!AI8+'18'!AI8+'19'!AI8+'20'!AI8+'21'!AI8+'22'!AI8+'23'!AI8 -> 0 | S2: ='1'!AJ8+'2'!AJ8+'3'!AJ8+'4'!AJ8+'5'!AJ8+'6'!AJ8+'7'!AJ8+'8'!AJ8+'9'!AJ8+'10'!AJ8+'11'!AJ8+'12'!AJ8+'13'!AJ8+'14'!AJ8+'15'!AJ8+'16'!AJ8+'17'!AJ8+'18'!AJ8+'19'!AJ8+'20'!AJ8+'21'!AJ8+'22'!AJ8+'23'!AJ8 -> 0 | T2: ='1'!AK8+'2'!AK8+'3'!AK8+'4'!AK8+'5'!AK8+'6'!AK8+'7'!AK8+'8'!AK8+'9'!AK8+'10'!AK8+'11'!AK8+'12'!AK8+'13'!AK8+'14'!AK8+'15'!AK8+'16'!AK8+'17'!AK8+'18'!AK8+'19'!AK8+'20'!AK8+'21'!AK8+'22'!AK8+'23'!AK8 -> 0 | U2: ='1'!AL8+'2'!AL8+'3'!AL8+'4'!AL8+'5'!AL8+'6'!AL8+'7'!AL8+'8'!AL8+'9'!AL8+'10'!AL8+'11'!AL8+'12'!AL8+'13'!AL8+'14'!AL8+'15'!AL8+'16'!AL8+'17'!AL8+'18'!AL8+'19'!AL8+'20'!AL8+'21'!AL8+'22'!AL8+'23'!AL8 -> 0 | V2: =SUM(H2:L2) -> 818.3968 | W2: =SUM(M2:U2) -> 0 | X2: =AVERAGE(X4:X27) -> 0.3025839 | AF2: =SUM('1'!AD8:AL8)+'1'!AA8 -> 130.67116 | AG2: =SUM('2'!AD8:AL8)+'2'!AA8 -> 2.4794096 | AH2: =SUM('3'!AD8:AL8)+'3'!AA8 -> 10.604034 | AI2: =SUM('4'!AD8:AL8)+'4'!AA8 -> 0.78928445 | AJ2: =SUM('5'!AD8:AL8)+'5'!AA8 -> 4.875626 | AK2: =SUM('6'!AD8:AL8)+'6'!AA8 -> 125.99565 | AL2: =SUM('7'!AD8:AL8)+'7'!AA8 -> 110.74819 | AM2: =SUM('8'!AD8:AL8)+'8'!AA8 -> 198.59706 | AN2: =SUM('9'!AD8:AL8)+'9'!AA8 -> 60.877048 | AO2: =SUM('10'!AD8:AL8)+'10'!AA8 -> 4.4448391 | AP2: =SUM('11'!AD8:AL8)+'11'!AA8 -> 5.662729 | AQ2: =SUM('12'!AD8:AL8)+'12'!AA8 -> 1.739707 | AR2: =SUM('13'!AD8:AL8)+'13'!AA8 -> 5.06182 | AS2: =SUM('14'!AD8:AL8)+'14'!AA8 -> 3.9221535 | AT2: =SUM('15'!AD8:AL8)+'15'!AA8 -> 54.087615 | AU2: =SUM('16'!AD8:AL8)+'16'!AA8 -> 21.543493 | AV2: =SUM('17'!AD8:AL8)+'17'!AA8 -> 36.664778 | AW2: =SUM('18'!AD8:AL8)+'18'!AA8 -> 9.1562725 | AX2: =SUM('19'!AD8:AL8)+'19'!AA8 -> 23.940915 | AY2: =SUM('20'!AD8:AL8)+'20'!AA8 -> 1.5071681 | AZ2: =SUM('21'!AD8:AL8)+'21'!AA8 -> 0.13750602 | BA2: =SUM('22'!AD8:AL8)+'22'!AA8 -> 0.4486375 | BB2: =SUM('23'!AD8:AL8)+'23'!AA8 -> 4.4417023 | BG2: 2025 | BH2: 0 | BI2: 0 | BK2: ='2 (RU)'!AB8+'6 (RU)'!AB8+'7 (RU)'!AB8+'9 (RU)'!AB8+'11 (RU)'!AB8+'12 (RU)'!AB8+'13 (RU)'!AB8+'16 (RU)'!AB8+'17 (RU)'!AB8+'18 (RU)'!AB8+'22 (RU)'!AB8 -> #DIV/0! | BL2: ='1 (RU)'!AB8+'2 (RU)'!AC8+'5 (RU)'!AB8+'6 (RU)'!AC8+'7 (RU)'!AC8+'9 (RU)'!AC8+'11 (RU)'!AC8+'12 (RU)'!AC8+'13 (RU)'!AC8+'15 (RU)'!AB8+'16 (RU)'!AC8+'17 (RU)'!AC8+'18 (RU)'!AC8+'19 (RU)'!AB8+'22 (RU)'!AC8 -> #DIV/0! | BN2: ='3 (RU)'!AB8+'4 (RU)'!AB8+'10 (RU)'!AB8+'20 (RU)'!AB8+'21 (RU)'!AB8+'23 (RU)'!AB8 -> #DIV/0! | BO2: ='8 (RU)'!AB8+'14 (RU)'!AB8 -> #DIV/0! | BP2: ='1 (RU)'!AD8+'2 (RU)'!AD8+'3 (RU)'!AD8+'4 (RU)'!AD8+'5 (RU)'!AD8+'6 (RU)'!AD8+'7 (RU)'!AD8+'8 (RU)'!AD8+'9 (RU)'!AD8+'10 (RU)'!AD8+'11 (RU)'!AD8+'12 (RU)'!AD8+'13 (RU)'!AD8+'14 (RU)'!AD8+'15 (RU)'!AD8+'16 (RU)'!AD8+'17 (RU)'!AD8+'18 (RU)'!AD8+'19 (RU)'!AD8+'20 (RU)'!AD8+'21 (RU)'!AD8+'22 (RU)'!AD8+'23 (RU)'!AD8 -> #DIV/0! | BQ2: ='1 (RU)'!AE8+'2 (RU)'!AE8+'3 (RU)'!AE8+'4 (RU)'!AE8+'5 (RU)'!AE8+'6 (RU)'!AE8+'7 (RU)'!AE8+'8 (RU)'!AE8+'9 (RU)'!AE8+'10 (RU)'!AE8+'11 (RU)'!AE8+'12 (RU)'!AE8+'13 (RU)'!AE8+'14 (RU)'!AE8+'15 (RU)'!AE8+'16 (RU)'!AE8+'17 (RU)'!AE8+'18 (RU)'!AE8+'19 (RU)'!AE8+'20 (RU)'!AE8+'21 (RU)'!AE8+'22 (RU)'!AE8+'23 (RU)'!AE8 -> #DIV/0! | BR2: ='1 (RU)'!AF8+'2 (RU)'!AF8+'3 (RU)'!AF8+'4 (RU)'!AF8+'5 (RU)'!AF8+'6 (RU)'!AF8+'7 (RU)'!AF8+'8 (RU)'!AF8+'9 (RU)'!AF8+'10 (RU)'!AF8+'11 (RU)'!AF8+'12 (RU)'!AF8+'13 (RU)'!AF8+'14 (RU)'!AF8+'15 (RU)'!AF8+'16 (RU)'!AF8+'17 (RU)'!AF8+'18 (RU)'!AF8+'19 (RU)'!AF8+'20 (RU)'!AF8+'21 (RU)'!AF8+'22 (RU)'!AF8+'23 (RU)'!AF8 -> #DIV/0! | BS2: ='1 (RU)'!AG8+'2 (RU)'!AG8+'3 (RU)'!AG8+'4 (RU)'!AG8+'5 (RU)'!AG8+'6 (RU)'!AG8+'7 (RU)'!AG8+'8 (RU)'!AG8+'9 (RU)'!AG8+'10 (RU)'!AG8+'11 (RU)'!AG8+'12 (RU)'!AG8+'13 (RU)'!AG8+'14 (RU)'!AG8+'15 (RU)'!AG8+'16 (RU)'!AG8+'17 (RU)'!AG8+'18 (RU)'!AG8+'19 (RU)'!AG8+'20 (RU)'!AG8+'21 (RU)'!AG8+'22 (RU)'!AG8+'23 (RU)'!AG8 -> #DIV/0! | BT2: ='1 (RU)'!AH8+'2 (RU)'!AH8+'3 (RU)'!AH8+'4 (RU)'!AH8+'5 (RU)'!AH8+'6 (RU)'!AH8+'7 (RU)'!AH8+'8 (RU)'!AH8+'9 (RU)'!AH8+'10 (RU)'!AH8+'11 (RU)'!AH8+'12 (RU)'!AH8+'13 (RU)'!AH8+'14 (RU)'!AH8+'15 (RU)'!AH8+'16 (RU)'!AH8+'17 (RU)'!AH8+'18 (RU)'!AH8+'19 (RU)'!AH8+'20 (RU)'!AH8+'21 (RU)'!AH8+'22 (RU)'!AH8+'23 (RU)'!AH8 -> #DIV/0! | BU2: ='1 (RU)'!AI8+'2 (RU)'!AI8+'3 (RU)'!AI8+'4 (RU)'!AI8+'5 (RU)'!AI8+'6 (RU)'!AI8+'7 (RU)'!AI8+'8 (RU)'!AI8+'9 (RU)'!AI8+'10 (RU)'!AI8+'11 (RU)'!AI8+'12 (RU)'!AI8+'13 (RU)'!AI8+'14 (RU)'!AI8+'15 (RU)'!AI8+'16 (RU)'!AI8+'17 (RU)'!AI8+'18 (RU)'!AI8+'19 (RU)'!AI8+'20 (RU)'!AI8+'21 (RU)'!AI8+'22 (RU)'!AI8+'23 (RU)'!AI8 -> #DIV/0! | BV2: ='1 (RU)'!AJ8+'2 (RU)'!AJ8+'3 (RU)'!AJ8+'4 (RU)'!AJ8+'5 (RU)'!AJ8+'6 (RU)'!AJ8+'7 (RU)'!AJ8+'8 (RU)'!AJ8+'9 (RU)'!AJ8+'10 (RU)'!AJ8+'11 (RU)'!AJ8+'12 (RU)'!AJ8+'13 (RU)'!AJ8+'14 (RU)'!AJ8+'15 (RU)'!AJ8+'16 (RU)'!AJ8+'17 (RU)'!AJ8+'18 (RU)'!AJ8+'19 (RU)'!AJ8+'20 (RU)'!AJ8+'21 (RU)'!AJ8+'22 (RU)'!AJ8+'23 (RU)'!AJ8 -> #DIV/0! | BW2: ='1 (RU)'!AK8+'2 (RU)'!AK8+'3 (RU)'!AK8+'4 (RU)'!AK8+'5 (RU)'!AK8+'6 (RU)'!AK8+'7 (RU)'!AK8+'8 (RU)'!AK8+'9 (RU)'!AK8+'10 (RU)'!AK8+'11 (RU)'!AK8+'12 (RU)'!AK8+'13 (RU)'!AK8+'14 (RU)'!AK8+'15 (RU)'!AK8+'16 (RU)'!AK8+'17 (RU)'!AK8+'18 (RU)'!AK8+'19 (RU)'!AK8+'20 (RU)'!AK8+'21 (RU)'!AK8+'22 (RU)'!AK8+'23 (RU)'!AK8 -> #DIV/0! | BX2: ='1 (RU)'!AL8+'2 (RU)'!AL8+'3 (RU)'!AL8+'4 (RU)'!AL8+'5 (RU)'!AL8+'6 (RU)'!AL8+'7 (RU)'!AL8+'8 (RU)'!AL8+'9 (RU)'!AL8+'10 (RU)'!AL8+'11 (RU)'!AL8+'12 (RU)'!AL8+'13 (RU)'!AL8+'14 (RU)'!AL8+'15 (RU)'!AL8+'16 (RU)'!AL8+'17 (RU)'!AL8+'18 (RU)'!AL8+'19 (RU)'!AL8+'20 (RU)'!AL8+'21 (RU)'!AL8+'22 (RU)'!AL8+'23 (RU)'!AL8 -> #DIV/0! | BY2: =SUM(BK2:BO2) -> #DIV/0! | BZ2: =SUM(BP2:BX2) -> #DIV/0! | CC2: =VLOOKUP(CC$1,emissions!$A$2:$B$5,2,FALSE)*BK2 -> #DIV/0! | CD2: =VLOOKUP(CD$1,emissions!$A$2:$B$5,2,FALSE)*BL2 -> #DIV/0! | CF2: =VLOOKUP(CF$1,emissions!$A$2:$B$5,2,FALSE)*BN2 -> #DIV/0! | CG2: =VLOOKUP(CG$1,emissions!$A$2:$B$5,2,FALSE)*BO2 -> #DIV/0! | CH2: =BP2*(emissions!$D$3*production!$B$4+emissions!$D$4*production!$C$4+emissions!$D$5*production!$D$4+emissions!$D$6*production!$E$4) -> #DIV/0! | CI2: =BQ2*(emissions!$D$3*production!$B$4+emissions!$D$4*production!$C$4+emissions!$D$5*production!$D$4+emissions!$D$6*production!$E$4) -> #DIV/0! | CJ2: =BR2*(emissions!$D$8*production!$B$6+emissions!$D$9*production!$C$6+emissions!$D$10*production!$D$6) -> #DIV/0! | CK2: =BS2*(emissions!$D$12*production!$B$8+emissions!$D$13*production!$C$8+emissions!$D$14*production!$D$8) -> #DIV/0! | CL2: =BT2*(emissions!$D$16*production!$B$10+production!$C$10*emissions!$D$17) -> #DIV/0! | CM2: =BU2*(emissions!$D$19*production!$B$12+production!$C$12*emissions!$D$20+emissions!$D$21*production!$D$12) -> #DIV/0! | CN2: =BV2*(emissions!$D$23*production!$B$14+production!$C$14*emissions!$D$24+emissions!$D$25*production!$D$14) -> #DIV/0! | CO2: =BW2*(emissions!$D$27*production!$B$16+production!$C$16*emissions!$D$28+production!$D$16*emissions!$D$29) -> #DIV/0! | CP2: 0 | CS2: =SUM(CC2:CP2) -> #DIV/0! | CT2: =SUM(CC2:CP2)/SUM(BK2:BX2) -> #DIV/0! | CU2: =(CT2-CW2) -> #DIV/0! | CV2: =CT2-CX2 -> #DIV/0! | CW2: =93.3*(1-BH2) -> 93.3 | CX2: =93.3*(1-BI2) -> 93.3 | CY2: =IF(G2<2028,0,IF(CT2>=CW2,CU2,IF(AND(CT2<CW2,CT2>=CX2),CV2,0))*SUM(BK2:BX2)) -> 0 | CZ2: =IF(CT2>=CW2,380*CY2,IF(AND(CT2<CW2,CT2>=CX2),100*CY2,0)) -> #DIV/0! | DA2: =IF(G2<2028,"",IF(CT2>=CW2,"Red",IF(AND(CT2<CW2,CT2>=CX2),"Yellow","Green"))) | DB2: =IF(G2<2028,0,IF(CT2<CX2,-CV2*SUM(BK2:BX2),0)) -> 0 | DC2: =DB2*380 -> 0 | DD2: 2025 | DQ2: 18115 | DR2: 7213 | DT2: 602 | DU2: 2049 | DV2: =DQ2*VLOOKUP(DQ$1,emissions!$A$2:$B$5,2,FALSE) -> 2644790 | DW2: =DR2*VLOOKUP(DR$1,emissions!$A$2:$B$5,2,FALSE) -> 1053098 | DY2: =DT2*VLOOKUP(DT$1,emissions!$A$2:$B$5,2,FALSE) -> 87290 | DZ2: =DU2*VLOOKUP(DU$1,emissions!$A$2:$B$5,2,FALSE) -> 231537 | EA2: =SUM(DV2:DZ2) -> 4016715 | EB2: =1/(SUM(DQ2:DU2)/EA2) -> 143.56178 | ED2: =SUM(EE2:ER2) -> #DIV/0! | EE2: =cost!$B$2*BK2 -> #DIV/0! | EF2: =cost!$B$3*BL2 -> #DIV/0! | EH2: =cost!$B$4*BN2 -> #DIV/0! | EI2: =cost!$B$5*$BO$2 -> #DIV/0! | EJ2: =BP2*(cost!$D$3*production!$B$4+production!$C$4*cost!$D$4+cost!$D$5*production!$D$4+production!$E$4*cost!$D$6) -> #DIV/0! | EK2: =BQ2*(cost!$D$3*production!$B$4+production!$C$4*cost!$D$4+cost!$D$5*production!$D$4+production!$E$4*cost!$D$6) -> #DIV/0! | EL2: =BR2*(cost!$D$8*production!$B$6+cost!$D$9*production!$C$6+$D$10*production!$D$6) -> #DIV/0! | EM2: =BS2*(cost!$D$12*production!$B$8+cost!$D$13*production!$C$8+cost!$D$14*production!$D$8) -> #DIV/0! | EN2: =BT2*(cost!$D$16*production!$B$10+production!$C$10*cost!$D$17) -> #DIV/0! | EO2: =BU2*(cost!$D$19*production!$B$12+production!$C$12*cost!$D$20+cost!$D$21*production!$D$12) -> #DIV/0! | EP2: =BV2*(cost!$D$23*production!$B$14+production!$C$14*cost!$D$24+cost!$D$25*production!$D$14) -> #DIV/0! | EQ2: =BW2*(cost!$D$27*production!$B$16+production!$C$16*cost!$D$28+cost!$D$29*production!$D$16) -> #DIV/0! | ER2: =BX2*(re!$H$10*re!$C$10+re!$H$11*re!$C$11+re!$H$12*re!$C$12+re!$H$13*re!$C$13+re!$H$14*re!$C$14) -> #DIV/0!
A3: Operational Measures | B3: k | C3: Savings | D3: t0 | G3: 2026 | H3: ='2'!AB9+'6'!AB9+'7'!AB9+'9'!AB9+'11'!AB9+'12'!AB9+'13'!AB9+'16'!AB9+'17'!AB9+'18'!AB9+'22'!AB9 -> 365.85749 | I3: ='1'!AB9+'2'!AC9+'5'!AB9+'6'!AC9+'7'!AC9+'9'!AC9+'11'!AC9+'12'!AC9+'13'!AC9+'15'!AB9+'16'!AC9+'17'!AC9+'18'!AC9+'19'!AB9+'22'!AC9 -> 235.04122 | K3: ='3'!AB9+'4'!AB9+'10'!AB9+'20'!AB9+'21'!AB9+'23'!AB9 -> 22.230214 | L3: ='8'!AB9+'14'!AB9 -> 205.29775 | M3: ='1'!AD9+'2'!AD9+'3'!AD9+'4'!AD9+'5'!AD9+'6'!AD9+'7'!AD9+'8'!AD9+'9'!AD9+'10'!AD9+'11'!AD9+'12'!AD9+'13'!AD9+'14'!AD9+'15'!AD9+'16'!AD9+'17'!AD9+'18'!AD9+'19'!AD9+'20'!AD9+'21'!AD9+'22'!AD9+'23'!AD9 -> 0.91768432 | N3: ='1'!AE9+'2'!AE9+'3'!AE9+'4'!AE9+'5'!AE9+'6'!AE9+'7'!AE9+'8'!AE9+'9'!AE9+'10'!AE9+'11'!AE9+'12'!AE9+'13'!AE9+'14'!AE9+'15'!AE9+'16'!AE9+'17'!AE9+'18'!AE9+'19'!AE9+'20'!AE9+'21'!AE9+'22'!AE9+'23'!AE9 -> 0.054420464 | O3: ='1'!AF9+'2'!AF9+'3'!AF9+'4'!AF9+'5'!AF9+'6'!AF9+'7'!AF9+'8'!AF9+'9'!AF9+'10'!AF9+'11'!AF9+'12'!AF9+'13'!AF9+'14'!AF9+'15'!AF9+'16'!AF9+'17'!AF9+'18'!AF9+'19'!AF9+'20'!AF9+'21'!AF9+'22'!AF9+'23'!AF9 -> 1.7588069 | P3: ='1'!AG9+'2'!AG9+'3'!AG9+'4'!AG9+'5'!AG9+'6'!AG9+'7'!AG9+'8'!AG9+'9'!AG9+'10'!AG9+'11'!AG9+'12'!AG9+'13'!AG9+'14'!AG9+'15'!AG9+'16'!AG9+'17'!AG9+'18'!AG9+'19'!AG9+'20'!AG9+'21'!AG9+'22'!AG9+'23'!AG9 -> 1.5991443 | Q3: ='1'!AH9+'2'!AH9+'3'!AH9+'4'!AH9+'5'!AH9+'6'!AH9+'7'!AH9+'8'!AH9+'9'!AH9+'10'!AH9+'11'!AH9+'12'!AH9+'13'!AH9+'14'!AH9+'15'!AH9+'16'!AH9+'17'!AH9+'18'!AH9+'19'!AH9+'20'!AH9+'21'!AH9+'22'!AH9+'23'!AH9 -> 0.041408169 | R3: ='1'!AI9+'2'!AI9+'3'!AI9+'4'!AI9+'5'!AI9+'6'!AI9+'7'!AI9+'8'!AI9+'9'!AI9+'10'!AI9+'11'!AI9+'12'!AI9+'13'!AI9+'14'!AI9+'15'!AI9+'16'!AI9+'17'!AI9+'18'!AI9+'19'!AI9+'20'!AI9+'21'!AI9+'22'!AI9+'23'!AI9 -> 0.27757831 | S3: ='1'!AJ9+'2'!AJ9+'3'!AJ9+'4'!AJ9+'5'!AJ9+'6'!AJ9+'7'!AJ9+'8'!AJ9+'9'!AJ9+'10'!AJ9+'11'!AJ9+'12'!AJ9+'13'!AJ9+'14'!AJ9+'15'!AJ9+'16'!AJ9+'17'!AJ9+'18'!AJ9+'19'!AJ9+'20'!AJ9+'21'!AJ9+'22'!AJ9+'23'!AJ9 -> 0.079269728 | T3: ='1'!AK9+'2'!AK9+'3'!AK9+'4'!AK9+'5'!AK9+'6'!AK9+'7'!AK9+'8'!AK9+'9'!AK9+'10'!AK9+'11'!AK9+'12'!AK9+'13'!AK9+'14'!AK9+'15'!AK9+'16'!AK9+'17'!AK9+'18'!AK9+'19'!AK9+'20'!AK9+'21'!AK9+'22'!AK9+'23'!AK9 -> 0.86862644 | U3: ='1'!AL9+'2'!AL9+'3'!AL9+'4'!AL9+'5'!AL9+'6'!AL9+'7'!AL9+'8'!AL9+'9'!AL9+'10'!AL9+'11'!AL9+'12'!AL9+'13'!AL9+'14'!AL9+'15'!AL9+'16'!AL9+'17'!AL9+'18'!AL9+'19'!AL9+'20'!AL9+'21'!AL9+'22'!AL9+'23'!AL9 -> 0.0020934281 | V3: =SUM(H3:L3) -> 828.42668 | W3: =SUM(M3:U3) -> 5.5990321 | Y3: =((M3+N3)*re!$D$2/re!$C$2+O3*re!$D$3/re!$C$3+P3*re!$D$4/re!$C$4+T3*re!$D$5/re!$C$5+U3*re!$D$6/re!$C$6) -> 9.5005286 | Z3: =SUM(AA3:AE3) -> 0.73298413 | AA3: =((Y3*277.8)/(re!$B$10*8760))*re!$C$10 -> 0.41556398 | AB3: =((Y3*277.8)/(re!$B$11*8760))*re!$C$11 -> 0.15450456 | AC3: =((Y3*277.8)/(re!$B$12*8760))*re!$C$12 -> 0.055793312 | AD3: =((Y3*277.8)/(re!$B$13*8760))*re!$C$13 -> 0.016374124 | AE3: =((Y3*277.8)/(re!$B$14*8760))*re!$C$14 -> 0.090748159 | AF3: =SUM('1'!AD9:AL9)+'1'!AA9 -> 133.15948 | AG3: =SUM('2'!AD9:AL9)+'2'!AA9 -> 2.5240186 | AH3: =SUM('3'!AD9:AL9)+'3'!AA9 -> 10.820074 | AI3: =SUM('4'!AD9:AL9)+'4'!AA9 -> 0.80544713 | AJ3: =SUM('5'!AD9:AL9)+'5'!AA9 -> 4.9630813 | AK3: =SUM('6'!AD9:AL9)+'6'!AA9 -> 128.23857 | AL3: =SUM('7'!AD9:AL9)+'7'!AA9 -> 112.73927 | AM3: =SUM('8'!AD9:AL9)+'8'!AA9 -> 202.83089 | AN3: =SUM('9'!AD9:AL9)+'9'!AA9 -> 61.969015 | AO3: =SUM('10'!AD9:AL9)+'10'!AA9 -> 4.5340992 | AP3: =SUM('11'!AD9:AL9)+'11'!AA9 -> 5.7700599 | AQ3: =SUM('12'!AD9:AL9)+'12'!AA9 -> 1.7726812 | AR3: =SUM('13'!AD9:AL9)+'13'!AA9 -> 5.1577613 | AS3: =SUM('14'!AD9:AL9)+'14'!AA9 -> 3.9997874 | AT3: =SUM('15'!AD9:AL9)+'15'!AA9 -> 55.057798 | AU3: =SUM('16'!AD9:AL9)+'16'!AA9 -> 21.951827 | AV3: =SUM('17'!AD9:AL9)+'17'!AA9 -> 37.359718 | AW3: =SUM('18'!AD9:AL9)+'18'!AA9 -> 9.3298196 | AX3: =SUM('19'!AD9:AL9)+'19'!AA9 -> 24.370349 | AY3: =SUM('20'!AD9:AL9)+'20'!AA9 -> 1.5380314 | AZ3: =SUM('21'!AD9:AL9)+'21'!AA9 -> 0.14018182 | BA3: =SUM('22'!AD9:AL9)+'22'!AA9 -> 0.45668482 | BB3: =SUM('23'!AD9:AL9)+'23'!AA9 -> 4.5370614 | BG3: 2026 | BH3: 0 | BI3: 0 | BK3: ='2 (RU)'!AB9+'6 (RU)'!AB9+'7 (RU)'!AB9+'9 (RU)'!AB9+'11 (RU)'!AB9+'12 (RU)'!AB9+'13 (RU)'!AB9+'16 (RU)'!AB9+'17 (RU)'!AB9+'18 (RU)'!AB9+'22 (RU)'!AB9 -> #DIV/0! | BL3: ='1 (RU)'!AB9+'2 (RU)'!AC9+'5 (RU)'!AB9+'6 (RU)'!AC9+'7 (RU)'!AC9+'9 (RU)'!AC9+'11 (RU)'!AC9+'12 (RU)'!AC9+'13 (RU)'!AC9+'15 (RU)'!AB9+'16 (RU)'!AC9+'17 (RU)'!AC9+'18 (RU)'!AC9+'19 (RU)'!AB9+'22 (RU)'!AC9 -> #DIV/0! | BN3: ='3 (RU)'!AB9+'4 (RU)'!AB9+'10 (RU)'!AB9+'20 (RU)'!AB9+'21 (RU)'!AB9+'23 (RU)'!AB9 -> #DIV/0! | BO3: ='8 (RU)'!AB9+'14 (RU)'!AB9 -> #DIV/0! | BP3: ='1 (RU)'!AD9+'2 (RU)'!AD9+'3 (RU)'!AD9+'4 (RU)'!AD9+'5 (RU)'!AD9+'6 (RU)'!AD9+'7 (RU)'!AD9+'8 (RU)'!AD9+'9 (RU)'!AD9+'10 (RU)'!AD9+'11 (RU)'!AD9+'12 (RU)'!AD9+'13 (RU)'!AD9+'14 (RU)'!AD9+'15 (RU)'!AD9+'16 (RU)'!AD9+'17 (RU)'!AD9+'18 (RU)'!AD9+'19 (RU)'!AD9+'20 (RU)'!AD9+'21 (RU)'!AD9+'22 (RU)'!AD9+'23 (RU)'!AD9 -> #DIV/0! | BQ3: ='1 (RU)'!AE9+'2 (RU)'!AE9+'3 (RU)'!AE9+'4 (RU)'!AE9+'5 (RU)'!AE9+'6 (RU)'!AE9+'7 (RU)'!AE9+'8 (RU)'!AE9+'9 (RU)'!AE9+'10 (RU)'!AE9+'11 (RU)'!AE9+'12 (RU)'!AE9+'13 (RU)'!AE9+'14 (RU)'!AE9+'15 (RU)'!AE9+'16 (RU)'!AE9+'17 (RU)'!AE9+'18 (RU)'!AE9+'19 (RU)'!AE9+'20 (RU)'!AE9+'21 (RU)'!AE9+'22 (RU)'!AE9+'23 (RU)'!AE9 -> #DIV/0! | BR3: ='1 (RU)'!AF9+'2 (RU)'!AF9+'3 (RU)'!AF9+'4 (RU)'!AF9+'5 (RU)'!AF9+'6 (RU)'!AF9+'7 (RU)'!AF9+'8 (RU)'!AF9+'9 (RU)'!AF9+'10 (RU)'!AF9+'11 (RU)'!AF9+'12 (RU)'!AF9+'13 (RU)'!AF9+'14 (RU)'!AF9+'15 (RU)'!AF9+'16 (RU)'!AF9+'17 (RU)'!AF9+'18 (RU)'!AF9+'19 (RU)'!AF9+'20 (RU)'!AF9+'21 (RU)'!AF9+'22 (RU)'!AF9+'23 (RU)'!AF9 -> #DIV/0! | BS3: ='1 (RU)'!AG9+'2 (RU)'!AG9+'3 (RU)'!AG9+'4 (RU)'!AG9+'5 (RU)'!AG9+'6 (RU)'!AG9+'7 (RU)'!AG9+'8 (RU)'!AG9+'9 (RU)'!AG9+'10 (RU)'!AG9+'11 (RU)'!AG9+'12 (RU)'!AG9+'13 (RU)'!AG9+'14 (RU)'!AG9+'15 (RU)'!AG9+'16 (RU)'!AG9+'17 (RU)'!AG9+'18 (RU)'!AG9+'19 (RU)'!AG9+'20 (RU)'!AG9+'21 (RU)'!AG9+'22 (RU)'!AG9+'23 (RU)'!AG9 -> #DIV/0! | BT3: ='1 (RU)'!AH9+'2 (RU)'!AH9+'3 (RU)'!AH9+'4 (RU)'!AH9+'5 (RU)'!AH9+'6 (RU)'!AH9+'7 (RU)'!AH9+'8 (RU)'!AH9+'9 (RU)'!AH9+'10 (RU)'!AH9+'11 (RU)'!AH9+'12 (RU)'!AH9+'13 (RU)'!AH9+'14 (RU)'!AH9+'15 (RU)'!AH9+'16 (RU)'!AH9+'17 (RU)'!AH9+'18 (RU)'!AH9+'19 (RU)'!AH9+'20 (RU)'!AH9+'21 (RU)'!AH9+'22 (RU)'!AH9+'23 (RU)'!AH9 -> #DIV/0! | BU3: ='1 (RU)'!AI9+'2 (RU)'!AI9+'3 (RU)'!AI9+'4 (RU)'!AI9+'5 (RU)'!AI9+'6 (RU)'!AI9+'7 (RU)'!AI9+'8 (RU)'!AI9+'9 (RU)'!AI9+'10 (RU)'!AI9+'11 (RU)'!AI9+'12 (RU)'!AI9+'13 (RU)'!AI9+'14 (RU)'!AI9+'15 (RU)'!AI9+'16 (RU)'!AI9+'17 (RU)'!AI9+'18 (RU)'!AI9+'19 (RU)'!AI9+'20 (RU)'!AI9+'21 (RU)'!AI9+'22 (RU)'!AI9+'23 (RU)'!AI9 -> #DIV/0! | BV3: ='1 (RU)'!AJ9+'2 (RU)'!AJ9+'3 (RU)'!AJ9+'4 (RU)'!AJ9+'5 (RU)'!AJ9+'6 (RU)'!AJ9+'7 (RU)'!AJ9+'8 (RU)'!AJ9+'9 (RU)'!AJ9+'10 (RU)'!AJ9+'11 (RU)'!AJ9+'12 (RU)'!AJ9+'13 (RU)'!AJ9+'14 (RU)'!AJ9+'15 (RU)'!AJ9+'16 (RU)'!AJ9+'17 (RU)'!AJ9+'18 (RU)'!AJ9+'19 (RU)'!AJ9+'20 (RU)'!AJ9+'21 (RU)'!AJ9+'22 (RU)'!AJ9+'23 (RU)'!AJ9 -> #DIV/0! | BW3: ='1 (RU)'!AK9+'2 (RU)'!AK9+'3 (RU)'!AK9+'4 (RU)'!AK9+'5 (RU)'!AK9+'6 (RU)'!AK9+'7 (RU)'!AK9+'8 (RU)'!AK9+'9 (RU)'!AK9+'10 (RU)'!AK9+'11 (RU)'!AK9+'12 (RU)'!AK9+'13 (RU)'!AK9+'14 (RU)'!AK9+'15 (RU)'!AK9+'16 (RU)'!AK9+'17 (RU)'!AK9+'18 (RU)'!AK9+'19 (RU)'!AK9+'20 (RU)'!AK9+'21 (RU)'!AK9+'22 (RU)'!AK9+'23 (RU)'!AK9 -> #DIV/0! | BX3: ='1 (RU)'!AL9+'2 (RU)'!AL9+'3 (RU)'!AL9+'4 (RU)'!AL9+'5 (RU)'!AL9+'6 (RU)'!AL9+'7 (RU)'!AL9+'8 (RU)'!AL9+'9 (RU)'!AL9+'10 (RU)'!AL9+'11 (RU)'!AL9+'12 (RU)'!AL9+'13 (RU)'!AL9+'14 (RU)'!AL9+'15 (RU)'!AL9+'16 (RU)'!AL9+'17 (RU)'!AL9+'18 (RU)'!AL9+'19 (RU)'!AL9+'20 (RU)'!AL9+'21 (RU)'!AL9+'22 (RU)'!AL9+'23 (RU)'!AL9 -> #DIV/0! | BY3: =SUM(BK3:BO3) -> #DIV/0! | BZ3: =SUM(BP3:BX3) -> #DIV/0! | CC3: =VLOOKUP(CC$1,emissions!$A$2:$B$5,2,FALSE)*BK3 -> #DIV/0! | CD3: =VLOOKUP(CD$1,emissions!$A$2:$B$5,2,FALSE)*BL3 -> #DIV/0! | CF3: =VLOOKUP(CF$1,emissions!$A$2:$B$5,2,FALSE)*BN3 -> #DIV/0! | CG3: =VLOOKUP(CG$1,emissions!$A$2:$B$5,2,FALSE)*BO3 -> #DIV/0! | CH3: =BP3*(emissions!$D$3*production!$B$4+emissions!$D$4*production!$C$4+emissions!$D$5*production!$D$4+emissions!$D$6*production!$E$4) -> #DIV/0! | CI3: =BQ3*(emissions!$D$3*production!$B$4+emissions!$D$4*production!$C$4+emissions!$D$5*production!$D$4+emissions!$D$6*production!$E$4) -> #DIV/0! | CJ3: =BR3*(emissions!$D$8*production!$B$6+emissions!$D$9*production!$C$6+emissions!$D$10*production!$D$6) -> #DIV/0! | CK3: =BS3*(emissions!$D$12*production!$B$8+emissions!$D$13*production!$C$8+emissions!$D$14*production!$D$8) -> #DIV/0! | CL3: =BT3*(emissions!$D$16*production!$B$10+production!$C$10*emissions!$D$17) -> #DIV/0! | CM3: =BU3*(emissions!$D$19*production!$B$12+production!$C$12*emissions!$D$20+emissions!$D$21*production!$D$12) -> #DIV/0! | CN3: =BV3*(emissions!$D$23*production!$B$14+production!$C$14*emissions!$D$24+emissions!$D$25*production!$D$14) -> #DIV/0! | CO3: =BW3*(emissions!$D$27*production!$B$16+production!$C$16*emissions!$D$28+production!$D$16*emissions!$D$29) -> #DIV/0! | CP3: 0 | CS3: =SUM(CC3:CP3) -> #DIV/0! | CT3: =SUM(CC3:CP3)/SUM(BK3:BX3) -> #DIV/0! | CU3: =(CT3-CW3) -> #DIV/0! | CV3: =CT3-CX3 -> #DIV/0! | CW3: =93.3*(1-BH3) -> 93.3 | CX3: =93.3*(1-BI3) -> 93.3 | CY3: =IF(G3<2028,0,IF(CT3>=CW3,CU3,IF(AND(CT3<CW3,CT3>=CX3),CV3,0))*SUM(BK3:BX3)) -> 0 | CZ3: =IF(CT3>=CW3,380*CY3,IF(AND(CT3<CW3,CT3>=CX3),100*CY3,0)) -> #DIV/0! | DA3: =IF(G3<2028,"",IF(CT3>=CW3,"Red",IF(AND(CT3<CW3,CT3>=CX3),"Yellow","Green"))) | DB3: =IF(G3<2028,0,IF(CT3<CX3,-CV3*SUM(BK3:BX3),0)) -> 0 | DC3: =DB3*380 -> 0 | DD3: 2026 | DO3: op costs (right) | DP3: sum op costs | DQ3: 17960 | DR3: 7825 | DT3: 614 | DU3: 2090 | DV3: =DQ3*VLOOKUP(DQ$1,emissions!$A$2:$B$5,2,FALSE) -> 2622160 | DW3: =DR3*VLOOKUP(DR$1,emissions!$A$2:$B$5,2,FALSE) -> 1142450 | DY3: =DT3*VLOOKUP(DT$1,emissions!$A$2:$B$5,2,FALSE) -> 89030 | DZ3: =DU3*VLOOKUP(DU$1,emissions!$A$2:$B$5,2,FALSE) -> 236170 | EA3: =SUM(DV3:DZ3) -> 4089810 | EB3: =1/(SUM(DQ3:DU3)/EA3) -> 143.55751 | ED3: =SUM(EE3:ER3) -> #DIV/0! | EE3: =cost!$B$2*BK3 -> #DIV/0! | EF3: =cost!$B$3*BL3 -> #DIV/0! | EH3: =cost!$B$4*BN3 -> #DIV/0! | EI3: =cost!$B$5*$BO$2 -> #DIV/0! | EJ3: =BP3*(cost!$D$3*production!$B$4+production!$C$4*cost!$D$4+cost!$D$5*production!$D$4+production!$E$4*cost!$D$6) -> #DIV/0! | EK3: =BQ3*(cost!$D$3*production!$B$4+production!$C$4*cost!$D$4+cost!$D$5*production!$D$4+production!$E$4*cost!$D$6) -> #DIV/0! | EL3: =BR3*(cost!$D$8*production!$B$6+cost!$D$9*production!$C$6+$D$10*production!$D$6) -> #DIV/0! | EM3: =BS3*(cost!$D$12*production!$B$8+cost!$D$13*production!$C$8+cost!$D$14*production!$D$8) -> #DIV/0! | EN3: =BT3*(cost!$D$16*production!$B$10+production!$C$10*cost!$D$17) -> #DIV/0! | EO3: =BU3*(cost!$D$19*production!$B$12+production!$C$12*cost!$D$20+cost!$D$21*production!$D$12) -> #DIV/0! | EP3: =BV3*(cost!$D$23*production!$B$14+production!$C$14*cost!$D$24+cost!$D$25*production!$D$14) -> #DIV/0! | EQ3: =BW3*(cost!$D$27*production!$B$16+production!$C$16*cost!$D$28+cost!$D$29*production!$D$16) -> #DIV/0! | ER3: =BX3*(re!$H$10*re!$C$10+re!$H$11*re!$C$11+re!$H$12*re!$C$12+re!$H$13*re!$C$13+re!$H$14*re!$C$14) -> #DIV/0!
A4: Hull coating + propeller | B4: 0.03 | C4: 0.13 | D4: 5 | G4: 2027 | H4: ='2'!AB10+'6'!AB10+'7'!AB10+'9'!AB10+'11'!AB10+'12'!AB10+'13'!AB10+'16'!AB10+'17'!AB10+'18'!AB10+'22'!AB10 -> 346.44752 | I4: ='1'!AB10+'2'!AC10+'5'!AB10+'6'!AC10+'7'!AC10+'9'!AC10+'11'!AC10+'12'!AC10+'13'!AC10+'15'!AB10+'16'!AC10+'17'!AC10+'18'!AC10+'19'!AB10+'22'!AC10 -> 259.39735 | K4: ='3'!AB10+'4'!AB10+'10'!AB10+'20'!AB10+'21'!AB10+'23'!AB10 -> 22.463129 | L4: ='8'!AB10+'14'!AB10 -> 207.40306 | M4: ='1'!AD10+'2'!AD10+'3'!AD10+'4'!AD10+'5'!AD10+'6'!AD10+'7'!AD10+'8'!AD10+'9'!AD10+'10'!AD10+'11'!AD10+'12'!AD10+'13'!AD10+'14'!AD10+'15'!AD10+'16'!AD10+'17'!AD10+'18'!AD10+'19'!AD10+'20'!AD10+'21'!AD10+'22'!AD10+'23'!AD10 -> 2.3774288 | N4: ='1'!AE10+'2'!AE10+'3'!AE10+'4'!AE10+'5'!AE10+'6'!AE10+'7'!AE10+'8'!AE10+'9'!AE10+'10'!AE10+'11'!AE10+'12'!AE10+'13'!AE10+'14'!AE10+'15'!AE10+'16'!AE10+'17'!AE10+'18'!AE10+'19'!AE10+'20'!AE10+'21'!AE10+'22'!AE10+'23'!AE10 -> 0.1409836 | O4: ='1'!AF10+'2'!AF10+'3'!AF10+'4'!AF10+'5'!AF10+'6'!AF10+'7'!AF10+'8'!AF10+'9'!AF10+'10'!AF10+'11'!AF10+'12'!AF10+'13'!AF10+'14'!AF10+'15'!AF10+'16'!AF10+'17'!AF10+'18'!AF10+'19'!AF10+'20'!AF10+'21'!AF10+'22'!AF10+'23'!AF10 -> 4.5562759 | P4: ='1'!AG10+'2'!AG10+'3'!AG10+'4'!AG10+'5'!AG10+'6'!AG10+'7'!AG10+'8'!AG10+'9'!AG10+'10'!AG10+'11'!AG10+'12'!AG10+'13'!AG10+'14'!AG10+'15'!AG10+'16'!AG10+'17'!AG10+'18'!AG10+'19'!AG10+'20'!AG10+'21'!AG10+'22'!AG10+'23'!AG10 -> 4.1430585 | Q4: ='1'!AH10+'2'!AH10+'3'!AH10+'4'!AH10+'5'!AH10+'6'!AH10+'7'!AH10+'8'!AH10+'9'!AH10+'10'!AH10+'11'!AH10+'12'!AH10+'13'!AH10+'14'!AH10+'15'!AH10+'16'!AH10+'17'!AH10+'18'!AH10+'19'!AH10+'20'!AH10+'21'!AH10+'22'!AH10+'23'!AH10 -> 0.10716314 | R4: ='1'!AI10+'2'!AI10+'3'!AI10+'4'!AI10+'5'!AI10+'6'!AI10+'7'!AI10+'8'!AI10+'9'!AI10+'10'!AI10+'11'!AI10+'12'!AI10+'13'!AI10+'14'!AI10+'15'!AI10+'16'!AI10+'17'!AI10+'18'!AI10+'19'!AI10+'20'!AI10+'21'!AI10+'22'!AI10+'23'!AI10 -> 0.71913032 | S4: ='1'!AJ10+'2'!AJ10+'3'!AJ10+'4'!AJ10+'5'!AJ10+'6'!AJ10+'7'!AJ10+'8'!AJ10+'9'!AJ10+'10'!AJ10+'11'!AJ10+'12'!AJ10+'13'!AJ10+'14'!AJ10+'15'!AJ10+'16'!AJ10+'17'!AJ10+'18'!AJ10+'19'!AJ10+'20'!AJ10+'21'!AJ10+'22'!AJ10+'23'!AJ10 -> 0.20515723 | T4: ='1'!AK10+'2'!AK10+'3'!AK10+'4'!AK10+'5'!AK10+'6'!AK10+'7'!AK10+'8'!AK10+'9'!AK10+'10'!AK10+'11'!AK10+'12'!AK10+'13'!AK10+'14'!AK10+'15'!AK10+'16'!AK10+'17'!AK10+'18'!AK10+'19'!AK10+'20'!AK10+'21'!AK10+'22'!AK10+'23'!AK10 -> 2.2509112 | U4: ='1'!AL10+'2'!AL10+'3'!AL10+'4'!AL10+'5'!AL10+'6'!AL10+'7'!AL10+'8'!AL10+'9'!AL10+'10'!AL10+'11'!AL10+'12'!AL10+'13'!AL10+'14'!AL10+'15'!AL10+'16'!AL10+'17'!AL10+'18'!AL10+'19'!AL10+'20'!AL10+'21'!AL10+'22'!AL10+'23'!AL10 -> 0.0054312862 | V4: =SUM(H4:L4) -> 835.71105 | W4: =SUM(M4:U4) -> 14.50554 | X4: =W4/W3-1 -> 1.5907228 | Y4: =((M4+N4)*re!$D$2/re!$C$2+O4*re!$D$3/re!$C$3+P4*re!$D$4/re!$C$4+T4*re!$D$5/re!$C$5+U4*re!$D$6/re!$C$6) -> 24.613702 | Z4: =SUM(AA4:AE4) -> 1.8989946 | AA4: =((Y4*277.8)/(re!$B$10*8760))*re!$C$10 -> 1.0766314 | AB4: =((Y4*277.8)/(re!$B$11*8760))*re!$C$11 -> 0.40028605 | AC4: =((Y4*277.8)/(re!$B$12*8760))*re!$C$12 -> 0.14454774 | AD4: =((Y4*277.8)/(re!$B$13*8760))*re!$C$13 -> 0.042421619 | AE4: =((Y4*277.8)/(re!$B$14*8760))*re!$C$14 -> 0.23510777 | AF4: =SUM('1'!AD10:AL10)+'1'!AA10 -> 135.69832 | AG4: =SUM('2'!AD10:AL10)+'2'!AA10 -> 2.5701218 | AH4: =SUM('3'!AD10:AL10)+'3'!AA10 -> 11.042625 | AI4: =SUM('4'!AD10:AL10)+'4'!AA10 -> 0.82214346 | AJ4: =SUM('5'!AD10:AL10)+'5'!AA10 -> 5.0533188 | AK4: =SUM('6'!AD10:AL10)+'6'!AA10 -> 130.54335 | AL4: =SUM('7'!AD10:AL10)+'7'!AA10 -> 114.79623 | AM4: =SUM('8'!AD10:AL10)+'8'!AA10 -> 207.29829 | AN4: =SUM('9'!AD10:AL10)+'9'!AA10 -> 63.09572 | AO4: =SUM('10'!AD10:AL10)+'10'!AA10 -> 4.6253186 | AP4: =SUM('11'!AD10:AL10)+'11'!AA10 -> 5.8808457 | AQ4: =SUM('12'!AD10:AL10)+'12'!AA10 -> 1.8067169 | AR4: =SUM('13'!AD10:AL10)+'13'!AA10 -> 5.2567909 | AS4: =SUM('14'!AD10:AL10)+'14'!AA10 -> 4.0817597 | AT4: =SUM('15'!AD10:AL10)+'15'!AA10 -> 56.058845 | AU4: =SUM('16'!AD10:AL10)+'16'!AA10 -> 22.373304 | AV4: =SUM('17'!AD10:AL10)+'17'!AA10 -> 38.07703 | AW4: =SUM('18'!AD10:AL10)+'18'!AA10 -> 9.5089533 | AX4: =SUM('19'!AD10:AL10)+'19'!AA10 -> 24.813444 | AY4: =SUM('20'!AD10:AL10)+'20'!AA10 -> 1.5699136 | AZ4: =SUM('21'!AD10:AL10)+'21'!AA10 -> 0.14294471 | BA4: =SUM('22'!AD10:AL10)+'22'!AA10 -> 0.46498815 | BB4: =SUM('23'!AD10:AL10)+'23'!AA10 -> 4.6356229 | BC4: =('1'!D10+'2'!D10+'3'!D10+'4'!D10+'5'!D10+'6'!D10+'7'!D10+'8'!D10+'9'!D10+'10'!D10+'12'!D10+'13'!D10+'14'!D10+'15'!D10+'16'!D10+'17'!D10+'18'!D10+'19'!D10+'20'!D10+'21'!D10+'22'!D10+'23'!D10)/('1'!D9+'2'!D9+'3'!D9+'4'!D9+'5'!D9+'6'!D9+'7'!D9+'8'!D9+'9'!D9+'10'!D9+'12'!D9+'13'!D9+'14'!D9+'15'!D9+'16'!D9+'17'!D9+'18'!D9+'19'!D9+'20'!D9+'21'!D9+'22'!D9+'23'!D9)-1 -> 1.0438371 | BD4: =('1'!E10+'2'!E10+'3'!E10+'4'!E10+'5'!E10+'6'!E10+'7'!E10+'8'!E10+'9'!E10+'10'!E10+'12'!E10+'13'!E10+'14'!E10+'15'!E10+'16'!E10+'17'!E10+'18'!E10+'19'!E10+'20'!E10+'21'!E10+'22'!E10+'23'!E10)/('1'!E9+'2'!E9+'3'!E9+'4'!E9+'5'!E9+'6'!E9+'7'!E9+'8'!E9+'9'!E9+'10'!E9+'12'!E9+'13'!E9+'14'!E9+'15'!E9+'16'!E9+'17'!E9+'18'!E9+'19'!E9+'20'!E9+'21'!E9+'22'!E9+'23'!E9)-1 -> 1.0438371 | BE4: =('1'!F10+'2'!F10+'3'!F10+'4'!F10+'5'!F10+'6'!F10+'7'!F10+'8'!F10+'9'!F10+'10'!F10+'12'!F10+'13'!F10+'14'!F10+'15'!F10+'16'!F10+'17'!F10+'18'!F10+'19'!F10+'20'!F10+'21'!F10+'22'!F10+'23'!F10)/('1'!F9+'2'!F9+'3'!F9+'4'!F9+'5'!F9+'6'!F9+'7'!F9+'8'!F9+'9'!F9+'10'!F9+'12'!F9+'13'!F9+'14'!F9+'15'!F9+'16'!F9+'17'!F9+'18'!F9+'19'!F9+'20'!F9+'21'!F9+'22'!F9+'23'!F9)-1 -> 1.0424592 | BF4: =W4/W3-1 -> 1.5907228 | BG4: 2027 | BH4: 0 | BI4: 0 | BK4: ='2 (RU)'!AB10+'6 (RU)'!AB10+'7 (RU)'!AB10+'9 (RU)'!AB10+'11 (RU)'!AB10+'12 (RU)'!AB10+'13 (RU)'!AB10+'16 (RU)'!AB10+'17 (RU)'!AB10+'18 (RU)'!AB10+'22 (RU)'!AB10 -> #DIV/0! | BL4: ='1 (RU)'!AB10+'2 (RU)'!AC10+'5 (RU)'!AB10+'6 (RU)'!AC10+'7 (RU)'!AC10+'9 (RU)'!AC10+'11 (RU)'!AC10+'12 (RU)'!AC10+'13 (RU)'!AC10+'15 (RU)'!AB10+'16 (RU)'!AC10+'17 (RU)'!AC10+'18 (RU)'!AC10+'19 (RU)'!AB10+'22 (RU)'!AC10 -> #DIV/0! | BN4: ='3 (RU)'!AB10+'4 (RU)'!AB10+'10 (RU)'!AB10+'20 (RU)'!AB10+'21 (RU)'!AB10+'23 (RU)'!AB10 -> #DIV/0! | BO4: ='8 (RU)'!AB10+'14 (RU)'!AB10 -> #DIV/0! | BP4: ='1 (RU)'!AD10+'2 (RU)'!AD10+'3 (RU)'!AD10+'4 (RU)'!AD10+'5 (RU)'!AD10+'6 (RU)'!AD10+'7 (RU)'!AD10+'8 (RU)'!AD10+'9 (RU)'!AD10+'10 (RU)'!AD10+'11 (RU)'!AD10+'12 (RU)'!AD10+'13 (RU)'!AD10+'14 (RU)'!AD10+'15 (RU)'!AD10+'16 (RU)'!AD10+'17 (RU)'!AD10+'18 (RU)'!AD10+'19 (RU)'!AD10+'20 (RU)'!AD10+'21 (RU)'!AD10+'22 (RU)'!AD10+'23 (RU)'!AD10 -> #DIV/0! | BQ4: ='1 (RU)'!AE10+'2 (RU)'!AE10+'3 (RU)'!AE10+'4 (RU)'!AE10+'5 (RU)'!AE10+'6 (RU)'!AE10+'7 (RU)'!AE10+'8 (RU)'!AE10+'9 (RU)'!AE10+'10 (RU)'!AE10+'11 (RU)'!AE10+'12 (RU)'!AE10+'13 (RU)'!AE10+'14 (RU)'!AE10+'15 (RU)'!AE10+'16 (RU)'!AE10+'17 (RU)'!AE10+'18 (RU)'!AE10+'19 (RU)'!AE10+'20 (RU)'!AE10+'21 (RU)'!AE10+'22 (RU)'!AE10+'23 (RU)'!AE10 -> #DIV/0! | BR4: ='1 (RU)'!AF10+'2 (RU)'!AF10+'3 (RU)'!AF10+'4 (RU)'!AF10+'5 (RU)'!AF10+'6 (RU)'!AF10+'7 (RU)'!AF10+'8 (RU)'!AF10+'9 (RU)'!AF10+'10 (RU)'!AF10+'11 (RU)'!AF10+'12 (RU)'!AF10+'13 (RU)'!AF10+'14 (RU)'!AF10+'15 (RU)'!AF10+'16 (RU)'!AF10+'17 (RU)'!AF10+'18 (RU)'!AF10+'19 (RU)'!AF10+'20 (RU)'!AF10+'21 (RU)'!AF10+'22 (RU)'!AF10+'23 (RU)'!AF10 -> #DIV/0! | BS4: ='1 (RU)'!AG10+'2 (RU)'!AG10+'3 (RU)'!AG10+'4 (RU)'!AG10+'5 (RU)'!AG10+'6 (RU)'!AG10+'7 (RU)'!AG10+'8 (RU)'!AG10+'9 (RU)'!AG10+'10 (RU)'!AG10+'11 (RU)'!AG10+'12 (RU)'!AG10+'13 (RU)'!AG10+'14 (RU)'!AG10+'15 (RU)'!AG10+'16 (RU)'!AG10+'17 (RU)'!AG10+'18 (RU)'!AG10+'19 (RU)'!AG10+'20 (RU)'!AG10+'21 (RU)'!AG10+'22 (RU)'!AG10+'23 (RU)'!AG10 -> #DIV/0! | BT4: ='1 (RU)'!AH10+'2 (RU)'!AH10+'3 (RU)'!AH10+'4 (RU)'!AH10+'5 (RU)'!AH10+'6 (RU)'!AH10+'7 (RU)'!AH10+'8 (RU)'!AH10+'9 (RU)'!AH10+'10 (RU)'!AH10+'11 (RU)'!AH10+'12 (RU)'!AH10+'13 (RU)'!AH10+'14 (RU)'!AH10+'15 (RU)'!AH10+'16 (RU)'!AH10+'17 (RU)'!AH10+'18 (RU)'!AH10+'19 (RU)'!AH10+'20 (RU)'!AH10+'21 (RU)'!AH10+'22 (RU)'!AH10+'23 (RU)'!AH10 -> #DIV/0! | BU4: ='1 (RU)'!AI10+'2 (RU)'!AI10+'3 (RU)'!AI10+'4 (RU)'!AI10+'5 (RU)'!AI10+'6 (RU)'!AI10+'7 (RU)'!AI10+'8 (RU)'!AI10+'9 (RU)'!AI10+'10 (RU)'!AI10+'11 (RU)'!AI10+'12 (RU)'!AI10+'13 (RU)'!AI10+'14 (RU)'!AI10+'15 (RU)'!AI10+'16 (RU)'!AI10+'17 (RU)'!AI10+'18 (RU)'!AI10+'19 (RU)'!AI10+'20 (RU)'!AI10+'21 (RU)'!AI10+'22 (RU)'!AI10+'23 (RU)'!AI10 -> #DIV/0! | BV4: ='1 (RU)'!AJ10+'2 (RU)'!AJ10+'3 (RU)'!AJ10+'4 (RU)'!AJ10+'5 (RU)'!AJ10+'6 (RU)'!AJ10+'7 (RU)'!AJ10+'8 (RU)'!AJ10+'9 (RU)'!AJ10+'10 (RU)'!AJ10+'11 (RU)'!AJ10+'12 (RU)'!AJ10+'13 (RU)'!AJ10+'14 (RU)'!AJ10+'15 (RU)'!AJ10+'16 (RU)'!AJ10+'17 (RU)'!AJ10+'18 (RU)'!AJ10+'19 (RU)'!AJ10+'20 (RU)'!AJ10+'21 (RU)'!AJ10+'22 (RU)'!AJ10+'23 (RU)'!AJ10 -> #DIV/0! | BW4: ='1 (RU)'!AK10+'2 (RU)'!AK10+'3 (RU)'!AK10+'4 (RU)'!AK10+'5 (RU)'!AK10+'6 (RU)'!AK10+'7 (RU)'!AK10+'8 (RU)'!AK10+'9 (RU)'!AK10+'10 (RU)'!AK10+'11 (RU)'!AK10+'12 (RU)'!AK10+'13 (RU)'!AK10+'14 (RU)'!AK10+'15 (RU)'!AK10+'16 (RU)'!AK10+'17 (RU)'!AK10+'18 (RU)'!AK10+'19 (RU)'!AK10+'20 (RU)'!AK10+'21 (RU)'!AK10+'22 (RU)'!AK10+'23 (RU)'!AK10 -> #DIV/0! | BX4: ='1 (RU)'!AL10+'2 (RU)'!AL10+'3 (RU)'!AL10+'4 (RU)'!AL10+'5 (RU)'!AL10+'6 (RU)'!AL10+'7 (RU)'!AL10+'8 (RU)'!AL10+'9 (RU)'!AL10+'10 (RU)'!AL10+'11 (RU)'!AL10+'12 (RU)'!AL10+'13 (RU)'!AL10+'14 (RU)'!AL10+'15 (RU)'!AL10+'16 (RU)'!AL10+'17 (RU)'!AL10+'18 (RU)'!AL10+'19 (RU)'!AL10+'20 (RU)'!AL10+'21 (RU)'!AL10+'22 (RU)'!AL10+'23 (RU)'!AL10 -> #DIV/0! | BY4: =SUM(BK4:BO4) -> #DIV/0! | BZ4: =SUM(BP4:BX4) -> #DIV/0! | CC4: =VLOOKUP(CC$1,emissions!$A$2:$B$5,2,FALSE)*BK4 -> #DIV/0! | CD4: =VLOOKUP(CD$1,emissions!$A$2:$B$5,2,FALSE)*BL4 -> #DIV/0! | CF4: =VLOOKUP(CF$1,emissions!$A$2:$B$5,2,FALSE)*BN4 -> #DIV/0! | CG4: =VLOOKUP(CG$1,emissions!$A$2:$B$5,2,FALSE)*BO4 -> #DIV/0! | CH4: =BP4*(emissions!$D$3*production!$B$4+emissions!$D$4*production!$C$4+emissions!$D$5*production!$D$4+emissions!$D$6*production!$E$4) -> #DIV/0! | CI4: =BQ4*(emissions!$D$3*production!$B$4+emissions!$D$4*production!$C$4+emissions!$D$5*production!$D$4+emissions!$D$6*production!$E$4) -> #DIV/0! | CJ4: =BR4*(emissions!$D$8*production!$B$6+emissions!$D$9*production!$C$6+emissions!$D$10*production!$D$6) -> #DIV/0! | CK4: =BS4*(emissions!$D$12*production!$B$8+emissions!$D$13*production!$C$8+emissions!$D$14*production!$D$8) -> #DIV/0! | CL4: =BT4*(emissions!$D$16*production!$B$10+production!$C$10*emissions!$D$17) -> #DIV/0! | CM4: =BU4*(emissions!$D$19*production!$B$12+production!$C$12*emissions!$D$20+emissions!$D$21*production!$D$12) -> #DIV/0! | CN4: =BV4*(emissions!$D$23*production!$B$14+production!$C$14*emissions!$D$24+emissions!$D$25*production!$D$14) -> #DIV/0! | CO4: =BW4*(emissions!$D$27*production!$B$16+production!$C$16*emissions!$D$28+production!$D$16*emissions!$D$29) -> #DIV/0! | CP4: 0 | CS4: =SUM(CC4:CP4) -> #DIV/0! | CT4: =SUM(CC4:CP4)/SUM(BK4:BX4) -> #DIV/0! | CU4: =(CT4-CW4) -> #DIV/0! | CV4: =CT4-CX4 -> #DIV/0! | CW4: =93.3*(1-BH4) -> 93.3 | CX4: =93.3*(1-BI4) -> 93.3 | CY4: =IF(G4<2028,0,IF(CT4>=CW4,CU4,IF(AND(CT4<CW4,CT4>=CX4),CV4,0))*SUM(BK4:BX4)) -> 0 | CZ4: =IF(CT4>=CW4,380*CY4,IF(AND(CT4<CW4,CT4>=CX4),100*CY4,0)) -> #DIV/0! | DA4: =IF(G4<2028,"",IF(CT4>=CW4,"Red",IF(AND(CT4<CW4,CT4>=CX4),"Yellow","Green"))) | DB4: =IF(G4<2028,0,IF(CT4<CX4,-CV4*SUM(BK4:BX4),0)) -> 0 | DC4: =DB4*380 -> 0 | DD4: 2027 | DQ4: 17666 | DR4: 8584 | DT4: 626 | DU4: 2132 | DV4: =DQ4*VLOOKUP(DQ$1,emissions!$A$2:$B$5,2,FALSE) -> 2579236 | DW4: =DR4*VLOOKUP(DR$1,emissions!$A$2:$B$5,2,FALSE) -> 1253264 | DY4: =DT4*VLOOKUP(DT$1,emissions!$A$2:$B$5,2,FALSE) -> 90770 | DZ4: =DU4*VLOOKUP(DU$1,emissions!$A$2:$B$5,2,FALSE) -> 240916 | EA4: =SUM(DV4:DZ4) -> 4164186 | EB4: =1/(SUM(DQ4:DU4)/EA4) -> 143.55302 | ED4: =SUM(EE4:ER4) -> #DIV/0! | EE4: =cost!$B$2*BK4 -> #DIV/0! | EF4: =cost!$B$3*BL4 -> #DIV/0! | EH4: =cost!$B$4*BN4 -> #DIV/0! | EI4: =cost!$B$5*$BO$2 -> #DIV/0! | EJ4: =BP4*(cost!$D$3*production!$B$4+production!$C$4*cost!$D$4+cost!$D$5*production!$D$4+production!$E$4*cost!$D$6) -> #DIV/0! | EK4: =BQ4*(cost!$D$3*production!$B$4+production!$C$4*cost!$D$4+cost!$D$5*production!$D$4+production!$E$4*cost!$D$6) -> #DIV/0! | EL4: =BR4*(cost!$D$8*production!$B$6+cost!$D$9*production!$C$6+$D$10*production!$D$6) -> #DIV/0! | EM4: =BS4*(cost!$D$12*production!$B$8+cost!$D$13*production!$C$8+cost!$D$14*production!$D$8) -> #DIV/0! | EN4: =BT4*(cost!$D$16*production!$B$10+production!$C$10*cost!$D$17) -> #DIV/0! | EO4: =BU4*(cost!$D$19*production!$B$12+production!$C$12*cost!$D$20+cost!$D$21*production!$D$12) -> #DIV/0! | EP4: =BV4*(cost!$D$23*production!$B$14+production!$C$14*cost!$D$24+cost!$D$25*production!$D$14) -> #DIV/0! | EQ4: =BW4*(cost!$D$27*production!$B$16+production!$C$16*cost!$D$28+cost!$D$29*production!$D$16) -> #DIV/0! | ER4: =BX4*(re!$H$10*re!$C$10+re!$H$11*re!$C$11+re!$H$12*re!$C$12+re!$H$13*re!$C$13+re!$H$14*re!$C$14) -> #DIV/0!
A5: Slow steaming | B5: 0.03 | C5: 0.2 | D5: 5 | G5: 2028 | H5: ='2'!AB11+'6'!AB11+'7'!AB11+'9'!AB11+'11'!AB11+'12'!AB11+'13'!AB11+'16'!AB11+'17'!AB11+'18'!AB11+'22'!AB11 -> 321.98847 | I5: ='1'!AB11+'2'!AC11+'5'!AB11+'6'!AC11+'7'!AC11+'9'!AC11+'11'!AC11+'12'!AC11+'13'!AC11+'15'!AB11+'16'!AC11+'17'!AC11+'18'!AC11+'19'!AB11+'22'!AC11 -> 285.63699 | K5: ='3'!AB11+'4'!AB11+'10'!AB11+'20'!AB11+'21'!AB11+'23'!AB11 -> 22.579446 | L5: ='8'!AB11+'14'!AB11 -> 208.43099 | M5: ='1'!AD11+'2'!AD11+'3'!AD11+'4'!AD11+'5'!AD11+'6'!AD11+'7'!AD11+'8'!AD11+'9'!AD11+'10'!AD11+'11'!AD11+'12'!AD11+'13'!AD11+'14'!AD11+'15'!AD11+'16'!AD11+'17'!AD11+'18'!AD11+'19'!AD11+'20'!AD11+'21'!AD11+'22'!AD11+'23'!AD11 -> 4.6698485 | N5: ='1'!AE11+'2'!AE11+'3'!AE11+'4'!AE11+'5'!AE11+'6'!AE11+'7'!AE11+'8'!AE11+'9'!AE11+'10'!AE11+'11'!AE11+'12'!AE11+'13'!AE11+'14'!AE11+'15'!AE11+'16'!AE11+'17'!AE11+'18'!AE11+'19'!AE11+'20'!AE11+'21'!AE11+'22'!AE11+'23'!AE11 -> 0.27692102 | O5: ='1'!AF11+'2'!AF11+'3'!AF11+'4'!AF11+'5'!AF11+'6'!AF11+'7'!AF11+'8'!AF11+'9'!AF11+'10'!AF11+'11'!AF11+'12'!AF11+'13'!AF11+'14'!AF11+'15'!AF11+'16'!AF11+'17'!AF11+'18'!AF11+'19'!AF11+'20'!AF11+'21'!AF11+'22'!AF11+'23'!AF11 -> 8.9491719 | P5: ='1'!AG11+'2'!AG11+'3'!AG11+'4'!AG11+'5'!AG11+'6'!AG11+'7'!AG11+'8'!AG11+'9'!AG11+'10'!AG11+'11'!AG11+'12'!AG11+'13'!AG11+'14'!AG11+'15'!AG11+'16'!AG11+'17'!AG11+'18'!AG11+'19'!AG11+'20'!AG11+'21'!AG11+'22'!AG11+'23'!AG11 -> 8.1383354 | Q5: ='1'!AH11+'2'!AH11+'3'!AH11+'4'!AH11+'5'!AH11+'6'!AH11+'7'!AH11+'8'!AH11+'9'!AH11+'10'!AH11+'11'!AH11+'12'!AH11+'13'!AH11+'14'!AH11+'15'!AH11+'16'!AH11+'17'!AH11+'18'!AH11+'19'!AH11+'20'!AH11+'21'!AH11+'22'!AH11+'23'!AH11 -> 0.21027338 | R5: ='1'!AI11+'2'!AI11+'3'!AI11+'4'!AI11+'5'!AI11+'6'!AI11+'7'!AI11+'8'!AI11+'9'!AI11+'10'!AI11+'11'!AI11+'12'!AI11+'13'!AI11+'14'!AI11+'15'!AI11+'16'!AI11+'17'!AI11+'18'!AI11+'19'!AI11+'20'!AI11+'21'!AI11+'22'!AI11+'23'!AI11 -> 1.4125725 | S5: ='1'!AJ11+'2'!AJ11+'3'!AJ11+'4'!AJ11+'5'!AJ11+'6'!AJ11+'7'!AJ11+'8'!AJ11+'9'!AJ11+'10'!AJ11+'11'!AJ11+'12'!AJ11+'13'!AJ11+'14'!AJ11+'15'!AJ11+'16'!AJ11+'17'!AJ11+'18'!AJ11+'19'!AJ11+'20'!AJ11+'21'!AJ11+'22'!AJ11+'23'!AJ11 -> 0.40257414 | T5: ='1'!AK11+'2'!AK11+'3'!AK11+'4'!AK11+'5'!AK11+'6'!AK11+'7'!AK11+'8'!AK11+'9'!AK11+'10'!AK11+'11'!AK11+'12'!AK11+'13'!AK11+'14'!AK11+'15'!AK11+'16'!AK11+'17'!AK11+'18'!AK11+'19'!AK11+'20'!AK11+'21'!AK11+'22'!AK11+'23'!AK11 -> 4.4224708 | U5: ='1'!AL11+'2'!AL11+'3'!AL11+'4'!AL11+'5'!AL11+'6'!AL11+'7'!AL11+'8'!AL11+'9'!AL11+'10'!AL11+'11'!AL11+'12'!AL11+'13'!AL11+'14'!AL11+'15'!AL11+'16'!AL11+'17'!AL11+'18'!AL11+'19'!AL11+'20'!AL11+'21'!AL11+'22'!AL11+'23'!AL11 -> 0.010683887 | V5: =SUM(H5:L5) -> 838.6359 | W5: =SUM(M5:U5) -> 28.492852 | X5: =W5/W4-1 -> 0.96427376 | Y5: =((M5+N5)*re!$D$2/re!$C$2+O5*re!$D$3/re!$C$3+P5*re!$D$4/re!$C$4+T5*re!$D$5/re!$C$5+U5*re!$D$6/re!$C$6) -> 48.348965 | Z5: =SUM(AA5:AE5) -> 3.7302161 | AA5: =((Y5*277.8)/(re!$B$10*8760))*re!$C$10 -> 2.114839 | AB5: =((Y5*277.8)/(re!$B$11*8760))*re!$C$11 -> 0.7862863 | AC5: =((Y5*277.8)/(re!$B$12*8760))*re!$C$12 -> 0.28393672 | AD5: =((Y5*277.8)/(re!$B$13*8760))*re!$C$13 -> 0.083329254 | AE5: =((Y5*277.8)/(re!$B$14*8760))*re!$C$14 -> 0.46182478 | AF5: =SUM('1'!AD11:AL11)+'1'!AA11 -> 138.29074 | AG5: =SUM('2'!AD11:AL11)+'2'!AA11 -> 2.6181408 | AH5: =SUM('3'!AD11:AL11)+'3'!AA11 -> 11.273012 | AI5: =SUM('4'!AD11:AL11)+'4'!AA11 -> 0.83949839 | AJ5: =SUM('5'!AD11:AL11)+'5'!AA11 -> 5.1470838 | AK5: =SUM('6'!AD11:AL11)+'6'!AA11 -> 132.92387 | AL5: =SUM('7'!AD11:AL11)+'7'!AA11 -> 116.93743 | AM5: =SUM('8'!AD11:AL11)+'8'!AA11 -> 212.08417 | AN5: =SUM('9'!AD11:AL11)+'9'!AA11 -> 64.266469 | AO5: =SUM('10'!AD11:AL11)+'10'!AA11 -> 4.7186374 | AP5: =SUM('11'!AD11:AL11)+'11'!AA11 -> 5.9959651 | AQ5: =SUM('12'!AD11:AL11)+'12'!AA11 -> 1.8420839 | AR5: =SUM('13'!AD11:AL11)+'13'!AA11 -> 5.3596942 | AS5: =SUM('14'!AD11:AL11)+'14'!AA11 -> 4.1697212 | AT5: =SUM('15'!AD11:AL11)+'15'!AA11 -> 57.099024 | AU5: =SUM('16'!AD11:AL11)+'16'!AA11 -> 22.811268 | AV5: =SUM('17'!AD11:AL11)+'17'!AA11 -> 38.822399 | AW5: =SUM('18'!AD11:AL11)+'18'!AA11 -> 9.6950939 | AX5: =SUM('19'!AD11:AL11)+'19'!AA11 -> 25.273861 | AY5: =SUM('20'!AD11:AL11)+'20'!AA11 -> 1.6030535 | AZ5: =SUM('21'!AD11:AL11)+'21'!AA11 -> 0.14581614 | BA5: =SUM('22'!AD11:AL11)+'22'!AA11 -> 0.47361606 | BB5: =SUM('23'!AD11:AL11)+'23'!AA11 -> 4.7381 | BC5: =('1'!D11+'2'!D11+'3'!D11+'4'!D11+'5'!D11+'6'!D11+'7'!D11+'8'!D11+'9'!D11+'10'!D11+'12'!D11+'13'!D11+'14'!D11+'15'!D11+'16'!D11+'17'!D11+'18'!D11+'19'!D11+'20'!D11+'21'!D11+'22'!D11+'23'!D11)/('1'!D10+'2'!D10+'3'!D10+'4'!D10+'5'!D10+'6'!D10+'7'!D10+'8'!D10+'9'!D10+'10'!D10+'12'!D10+'13'!D10+'14'!D10+'15'!D10+'16'!D10+'17'!D10+'18'!D10+'19'!D10+'20'!D10+'21'!D10+'22'!D10+'23'!D10)-1 -> 0.53264861 | BD5: =('1'!E11+'2'!E11+'3'!E11+'4'!E11+'5'!E11+'6'!E11+'7'!E11+'8'!E11+'9'!E11+'10'!E11+'12'!E11+'13'!E11+'14'!E11+'15'!E11+'16'!E11+'17'!E11+'18'!E11+'19'!E11+'20'!E11+'21'!E11+'22'!E11+'23'!E11)/('1'!E10+'2'!E10+'3'!E10+'4'!E10+'5'!E10+'6'!E10+'7'!E10+'8'!E10+'9'!E10+'10'!E10+'12'!E10+'13'!E10+'14'!E10+'15'!E10+'16'!E10+'17'!E10+'18'!E10+'19'!E10+'20'!E10+'21'!E10+'22'!E10+'23'!E10)-1 -> 0.53264861 | BE5: =('1'!F11+'2'!F11+'3'!F11+'4'!F11+'5'!F11+'6'!F11+'7'!F11+'8'!F11+'9'!F11+'10'!F11+'12'!F11+'13'!F11+'14'!F11+'15'!F11+'16'!F11+'17'!F11+'18'!F11+'19'!F11+'20'!F11+'21'!F11+'22'!F11+'23'!F11)/('1'!F10+'2'!F10+'3'!F10+'4'!F10+'5'!F10+'6'!F10+'7'!F10+'8'!F10+'9'!F10+'10'!F10+'12'!F10+'13'!F10+'14'!F10+'15'!F10+'16'!F10+'17'!F10+'18'!F10+'19'!F10+'20'!F10+'21'!F10+'22'!F10+'23'!F10)-1 -> 0.53181896 | BF5: =W5/W4-1 -> 0.96427376 | BG5: 2028 | BH5: 0.04 | BI5: 0.17 | BJ5: =BI5-BH5 -> 0.13 | BK5: ='2 (RU)'!AB11+'6 (RU)'!AB11+'7 (RU)'!AB11+'9 (RU)'!AB11+'11 (RU)'!AB11+'12 (RU)'!AB11+'13 (RU)'!AB11+'16 (RU)'!AB11+'17 (RU)'!AB11+'18 (RU)'!AB11+'22 (RU)'!AB11 -> #DIV/0! | BL5: ='1 (RU)'!AB11+'2 (RU)'!AC11+'5 (RU)'!AB11+'6 (RU)'!AC11+'7 (RU)'!AC11+'9 (RU)'!AC11+'11 (RU)'!AC11+'12 (RU)'!AC11+'13 (RU)'!AC11+'15 (RU)'!AB11+'16 (RU)'!AC11+'17 (RU)'!AC11+'18 (RU)'!AC11+'19 (RU)'!AB11+'22 (RU)'!AC11 -> #DIV/0! | BN5: ='3 (RU)'!AB11+'4 (RU)'!AB11+'10 (RU)'!AB11+'20 (RU)'!AB11+'21 (RU)'!AB11+'23 (RU)'!AB11 -> #DIV/0! | BO5: ='8 (RU)'!AB11+'14 (RU)'!AB11 -> #DIV/0! | BP5: ='1 (RU)'!AD11+'2 (RU)'!AD11+'3 (RU)'!AD11+'4 (RU)'!AD11+'5 (RU)'!AD11+'6 (RU)'!AD11+'7 (RU)'!AD11+'8 (RU)'!AD11+'9 (RU)'!AD11+'10 (RU)'!AD11+'11 (RU)'!AD11+'12 (RU)'!AD11+'13 (RU)'!AD11+'14 (RU)'!AD11+'15 (RU)'!AD11+'16 (RU)'!AD11+'17 (RU)'!AD11+'18 (RU)'!AD11+'19 (RU)'!AD11+'20 (RU)'!AD11+'21 (RU)'!AD11+'22 (RU)'!AD11+'23 (RU)'!AD11 -> #DIV/0! | BQ5: ='1 (RU)'!AE11+'2 (RU)'!AE11+'3 (RU)'!AE11+'4 (RU)'!AE11+'5 (RU)'!AE11+'6 (RU)'!AE11+'7 (RU)'!AE11+'8 (RU)'!AE11+'9 (RU)'!AE11+'10 (RU)'!AE11+'11 (RU)'!AE11+'12 (RU)'!AE11+'13 (RU)'!AE11+'14 (RU)'!AE11+'15 (RU)'!AE11+'16 (RU)'!AE11+'17 (RU)'!AE11+'18 (RU)'!AE11+'19 (RU)'!AE11+'20 (RU)'!AE11+'21 (RU)'!AE11+'22 (RU)'!AE11+'23 (RU)'!AE11 -> #DIV/0! | BR5: ='1 (RU)'!AF11+'2 (RU)'!AF11+'3 (RU)'!AF11+'4 (RU)'!AF11+'5 (RU)'!AF11+'6 (RU)'!AF11+'7 (RU)'!AF11+'8 (RU)'!AF11+'9 (RU)'!AF11+'10 (RU)'!AF11+'11 (RU)'!AF11+'12 (RU)'!AF11+'13 (RU)'!AF11+'14 (RU)'!AF11+'15 (RU)'!AF11+'16 (RU)'!AF11+'17 (RU)'!AF11+'18 (RU)'!AF11+'19 (RU)'!AF11+'20 (RU)'!AF11+'21 (RU)'!AF11+'22 (RU)'!AF11+'23 (RU)'!AF11 -> #DIV/0! | BS5: ='1 (RU)'!AG11+'2 (RU)'!AG11+'3 (RU)'!AG11+'4 (RU)'!AG11+'5 (RU)'!AG11+'6 (RU)'!AG11+'7 (RU)'!AG11+'8 (RU)'!AG11+'9 (RU)'!AG11+'10 (RU)'!AG11+'11 (RU)'!AG11+'12 (RU)'!AG11+'13 (RU)'!AG11+'14 (RU)'!AG11+'15 (RU)'!AG11+'16 (RU)'!AG11+'17 (RU)'!AG11+'18 (RU)'!AG11+'19 (RU)'!AG11+'20 (RU)'!AG11+'21 (RU)'!AG11+'22 (RU)'!AG11+'23 (RU)'!AG11 -> #DIV/0! | BT5: ='1 (RU)'!AH11+'2 (RU)'!AH11+'3 (RU)'!AH11+'4 (RU)'!AH11+'5 (RU)'!AH11+'6 (RU)'!AH11+'7 (RU)'!AH11+'8 (RU)'!AH11+'9 (RU)'!AH11+'10 (RU)'!AH11+'11 (RU)'!AH11+'12 (RU)'!AH11+'13 (RU)'!AH11+'14 (RU)'!AH11+'15 (RU)'!AH11+'16 (RU)'!AH11+'17 (RU)'!AH11+'18 (RU)'!AH11+'19 (RU)'!AH11+'20 (RU)'!AH11+'21 (RU)'!AH11+'22 (RU)'!AH11+'23 (RU)'!AH11 -> #DIV/0! | BU5: ='1 (RU)'!AI11+'2 (RU)'!AI11+'3 (RU)'!AI11+'4 (RU)'!AI11+'5 (RU)'!AI11+'6 (RU)'!AI11+'7 (RU)'!AI11+'8 (RU)'!AI11+'9 (RU)'!AI11+'10 (RU)'!AI11+'11 (RU)'!AI11+'12 (RU)'!AI11+'13 (RU)'!AI11+'14 (RU)'!AI11+'15 (RU)'!AI11+'16 (RU)'!AI11+'17 (RU)'!AI11+'18 (RU)'!AI11+'19 (RU)'!AI11+'20 (RU)'!AI11+'21 (RU)'!AI11+'22 (RU)'!AI11+'23 (RU)'!AI11 -> #DIV/0! | BV5: ='1 (RU)'!AJ11+'2 (RU)'!AJ11+'3 (RU)'!AJ11+'4 (RU)'!AJ11+'5 (RU)'!AJ11+'6 (RU)'!AJ11+'7 (RU)'!AJ11+'8 (RU)'!AJ11+'9 (RU)'!AJ11+'10 (RU)'!AJ11+'11 (RU)'!AJ11+'12 (RU)'!AJ11+'13 (RU)'!AJ11+'14 (RU)'!AJ11+'15 (RU)'!AJ11+'16 (RU)'!AJ11+'17 (RU)'!AJ11+'18 (RU)'!AJ11+'19 (RU)'!AJ11+'20 (RU)'!AJ11+'21 (RU)'!AJ11+'22 (RU)'!AJ11+'23 (RU)'!AJ11 -> #DIV/0! | BW5: ='1 (RU)'!AK11+'2 (RU)'!AK11+'3 (RU)'!AK11+'4 (RU)'!AK11+'5 (RU)'!AK11+'6 (RU)'!AK11+'7 (RU)'!AK11+'8 (RU)'!AK11+'9 (RU)'!AK11+'10 (RU)'!AK11+'11 (RU)'!AK11+'12 (RU)'!AK11+'13 (RU)'!AK11+'14 (RU)'!AK11+'15 (RU)'!AK11+'16 (RU)'!AK11+'17 (RU)'!AK11+'18 (RU)'!AK11+'19 (RU)'!AK11+'20 (RU)'!AK11+'21 (RU)'!AK11+'22 (RU)'!AK11+'23 (RU)'!AK11 -> #DIV/0! | BX5: ='1 (RU)'!AL11+'2 (RU)'!AL11+'3 (RU)'!AL11+'4 (RU)'!AL11+'5 (RU)'!AL11+'6 (RU)'!AL11+'7 (RU)'!AL11+'8 (RU)'!AL11+'9 (RU)'!AL11+'10 (RU)'!AL11+'11 (RU)'!AL11+'12 (RU)'!AL11+'13 (RU)'!AL11+'14 (RU)'!AL11+'15 (RU)'!AL11+'16 (RU)'!AL11+'17 (RU)'!AL11+'18 (RU)'!AL11+'19 (RU)'!AL11+'20 (RU)'!AL11+'21 (RU)'!AL11+'22 (RU)'!AL11+'23 (RU)'!AL11 -> #DIV/0! | BY5: =SUM(BK5:BO5) -> #DIV/0! | BZ5: =SUM(BP5:BX5) -> #DIV/0! | CC5: =VLOOKUP(CC$1,emissions!$A$2:$B$5,2,FALSE)*BK5 -> #DIV/0! | CD5: =VLOOKUP(CD$1,emissions!$A$2:$B$5,2,FALSE)*BL5 -> #DIV/0! | CF5: =VLOOKUP(CF$1,emissions!$A$2:$B$5,2,FALSE)*BN5 -> #DIV/0! | CG5: =VLOOKUP(CG$1,emissions!$A$2:$B$5,2,FALSE)*BO5 -> #DIV/0! | CH5: =BP5*(emissions!$D$3*production!$B$4+emissions!$D$4*production!$C$4+emissions!$D$5*production!$D$4+emissions!$D$6*production!$E$4) -> #DIV/0! | CI5: =BQ5*(emissions!$D$3*production!$B$4+emissions!$D$4*production!$C$4+emissions!$D$5*production!$D$4+emissions!$D$6*production!$E$4) -> #DIV/0! | CJ5: =BR5*(emissions!$D$8*production!$B$6+emissions!$D$9*production!$C$6+emissions!$D$10*production!$D$6) -> #DIV/0! | CK5: =BS5*(emissions!$D$12*production!$B$8+emissions!$D$13*production!$C$8+emissions!$D$14*production!$D$8) -> #DIV/0! | CL5: =BT5*(emissions!$D$16*production!$B$10+production!$C$10*emissions!$D$17) -> #DIV/0! | CM5: =BU5*(emissions!$D$19*production!$B$12+production!$C$12*emissions!$D$20+emissions!$D$21*production!$D$12) -> #DIV/0! | CN5: =BV5*(emissions!$D$23*production!$B$14+production!$C$14*emissions!$D$24+emissions!$D$25*production!$D$14) -> #DIV/0! | CO5: =BW5*(emissions!$D$27*production!$B$16+production!$C$16*emissions!$D$28+production!$D$16*emissions!$D$29) -> #DIV/0! | CP5: 0 | CS5: =SUM(CC5:CP5) -> #DIV/0! | CT5: =SUM(CC5:CP5)/SUM(BK5:BX5) -> #DIV/0! | CU5: =(CT5-CW5) -> #DIV/0! | CV5: =CT5-CX5 -> #DIV/0! | CW5: =93.3*(1-BH5) -> 89.568 | CX5: =93.3*(1-BI5) -> 77.439 | CY5: =IF(G5<2028,0,IF(CT5>=CW5,CU5,IF(AND(CT5<CW5,CT5>=CX5),CV5,0))*SUM(BK5:BX5)) -> #DIV/0! | CZ5: =IF(CT5>=CW5,380*CY5,IF(AND(CT5<CW5,CT5>=CX5),100*CY5,0)) -> #DIV/0! | DA5: =IF(G5<2028,"",IF(CT5>=CW5,"Red",IF(AND(CT5<CW5,CT5>=CX5),"Yellow","Green"))) -> #DIV/0! | DB5: =IF(G5<2028,0,IF(CT5<CX5,-CV5*SUM(BK5:BX5),0)) -> #DIV/0! | DC5: =DB5*380 -> #DIV/0! | DD5: 2028 | DE5: =CY5-DB5 -> #DIV/0! | DF5: =CS5 -> #DIV/0! | DG5: 2028 | DH5: =CW5*SUM(BK5:BX5) -> #DIV/0! | DI5: =CX5*SUM(BK5:BX5) -> #DIV/0! | DJ5: =DI5 -> #DIV/0! | DK5: =DH5-DI5 -> #DIV/0! | DL5: =MAX(DH5:DK5) -> #DIV/0! | DM5: =(CZ5-DC5)/1000000 -> #DIV/0! | DN5: =DE5/1000000 -> #DIV/0! | DO5: =ED5/1000000 -> #DIV/0! | DP5: =DM5+DO5 -> #DIV/0! | DQ5: 17206 | DR5: 9518 | DT5: 639 | DU5: 2174 | DV5: =DQ5*VLOOKUP(DQ$1,emissions!$A$2:$B$5,2,FALSE) -> 2512076 | DW5: =DR5*VLOOKUP(DR$1,emissions!$A$2:$B$5,2,FALSE) -> 1389628 | DY5: =DT5*VLOOKUP(DT$1,emissions!$A$2:$B$5,2,FALSE) -> 92655 | DZ5: =DU5*VLOOKUP(DU$1,emissions!$A$2:$B$5,2,FALSE) -> 245662 | EA5: =SUM(DV5:DZ5) -> 4240021 | EB5: =1/(SUM(DQ5:DU5)/EA5) -> 143.54948 | ED5: =SUM(EE5:ER5) -> #DIV/0! | EE5: =cost!$B$2*BK5 -> #DIV/0! | EF5: =cost!$B$3*BL5 -> #DIV/0! | EH5: =cost!$B$4*BN5 -> #DIV/0! | EI5: =cost!$B$5*$BO$2 -> #DIV/0! | EJ5: =BP5*(cost!$D$3*production!$B$4+production!$C$4*cost!$D$4+cost!$D$5*production!$D$4+production!$E$4*cost!$D$6) -> #DIV/0! | EK5: =BQ5*(cost!$D$3*production!$B$4+production!$C$4*cost!$D$4+cost!$D$5*production!$D$4+production!$E$4*cost!$D$6) -> #DIV/0! | EL5: =BR5*(cost!$D$8*production!$B$6+cost!$D$9*production!$C$6+$D$10*production!$D$6) -> #DIV/0! | EM5: =BS5*(cost!$D$12*production!$B$8+cost!$D$13*production!$C$8+cost!$D$14*production!$D$8) -> #DIV/0! | EN5: =BT5*(cost!$D$16*production!$B$10+production!$C$10*cost!$D$17) -> #DIV/0! | EO5: =BU5*(cost!$D$19*production!$B$12+production!$C$12*cost!$D$20+cost!$D$21*production!$D$12) -> #DIV/0! | EP5: =BV5*(cost!$D$23*production!$B$14+production!$C$14*cost!$D$24+cost!$D$25*production!$D$14) -> #DIV/0! | EQ5: =BW5*(cost!$D$27*production!$B$16+production!$C$16*cost!$D$28+cost!$D$29*production!$D$16) -> #DIV/0! | ER5: =BX5*(re!$H$10*re!$C$10+re!$H$11*re!$C$11+re!$H$12*re!$C$12+re!$H$13*re!$C$13+re!$H$14*re!$C$14) -> #DIV/0!
